 * Serving Flask app 'app'
 * Debug mode: on
[31m[1mWARNING: This is a development server. Do not use it in a production deployment. Use a production WSGI server instead.[0m
 * Running on http://127.0.0.1:5500
[33mPress CTRL+C to quit[0m
 * Restarting with stat
 * Debugger is active!
 * Debugger PIN: 100-709-659
 * Serving Flask app 'app'
 * Debug mode: on
Address already in use
Port 5500 is in use by another program. Either identify and stop that program, or start the server with a different port.
 * Serving Flask app 'app'
 * Debug mode: on
Address already in use
Port 5500 is in use by another program. Either identify and stop that program, or start the server with a different port.
 * Serving Flask app 'app'
 * Debug mode: on
Address already in use
Port 5500 is in use by another program. Either identify and stop that program, or start the server with a different port.
 * Serving Flask app 'app'
 * Debug mode: on
Address already in use
Port 5500 is in use by another program. Either identify and stop that program, or start the server with a different port.
 * Serving Flask app 'app'
 * Debug mode: on
Address already in use
Port 5500 is in use by another program. Either identify and stop that program, or start the server with a different port.
 * Serving Flask app 'app'
 * Debug mode: on
Address already in use
Port 5500 is in use by another program. Either identify and stop that program, or start the server with a different port.
 * Serving Flask app 'app'
 * Debug mode: on
Address already in use
Port 5500 is in use by another program. Either identify and stop that program, or start the server with a different port.
 * Serving Flask app 'app'
 * Debug mode: on
Address already in use
Port 5500 is in use by another program. Either identify and stop that program, or start the server with a different port.
 * Serving Flask app 'app'
 * Debug mode: on
Address already in use
Port 5500 is in use by another program. Either identify and stop that program, or start the server with a different port.
 * Serving Flask app 'app'
 * Debug mode: on
Address already in use
Port 5500 is in use by another program. Either identify and stop that program, or start the server with a different port.
 * Serving Flask app 'app'
 * Debug mode: on
Address already in use
Port 5500 is in use by another program. Either identify and stop that program, or start the server with a different port.
 * Serving Flask app 'app'
 * Debug mode: on
Address already in use
Port 5500 is in use by another program. Either identify and stop that program, or start the server with a different port.
 * Serving Flask app 'app'
 * Debug mode: on
Address already in use
Port 5500 is in use by another program. Either identify and stop that program, or start the server with a different port.
 * Serving Flask app 'app'
 * Debug mode: on
Address already in use
Port 5500 is in use by another program. Either identify and stop that program, or start the server with a different port.
 * Detected change in '/mnt/c/Users/Aryan/Desktop/m122_live_currency/Code/app.py', reloading
 * Restarting with stat
 * Debugger is active!
 * Debugger PIN: 100-709-659
 * Detected change in '/mnt/c/Users/Aryan/Desktop/m122_live_currency/Code/app.py', reloading
 * Restarting with stat
 * Debugger is active!
 * Debugger PIN: 100-709-659
 * Serving Flask app 'app'
 * Debug mode: on
Address already in use
Port 5500 is in use by another program. Either identify and stop that program, or start the server with a different port.
 * Detected change in '/mnt/c/Users/Aryan/Desktop/m122_live_currency/Code/app.py', reloading
 * Restarting with stat
 * Debugger is active!
 * Debugger PIN: 100-709-659
 * Detected change in '/mnt/c/Users/Aryan/Desktop/m122_live_currency/Code/app.py', reloading
 * Restarting with stat
 * Debugger is active!
 * Debugger PIN: 100-709-659
 * Serving Flask app 'app'
 * Debug mode: on
Address already in use
Port 5500 is in use by another program. Either identify and stop that program, or start the server with a different port.
 * Detected change in '/mnt/c/Users/Aryan/Desktop/m122_live_currency/Code/app.py', reloading
 * Restarting with stat
 * Debugger is active!
 * Debugger PIN: 100-709-659
 * Detected change in '/mnt/c/Users/Aryan/Desktop/m122_live_currency/Code/app.py', reloading
 * Restarting with stat
 * Debugger is active!
 * Debugger PIN: 100-709-659
 * Detected change in '/mnt/c/Users/Aryan/Desktop/m122_live_currency/Code/app.py', reloading
 * Restarting with stat
 * Debugger is active!
 * Debugger PIN: 100-709-659
 * Detected change in '/mnt/c/Users/Aryan/Desktop/m122_live_currency/Code/app.py', reloading
 * Restarting with stat
 * Debugger is active!
 * Debugger PIN: 100-709-659
 * Detected change in '/mnt/c/Users/Aryan/Desktop/m122_live_currency/Code/app.py', reloading
 * Restarting with stat
 * Debugger is active!
 * Debugger PIN: 100-709-659
 * Serving Flask app 'app'
 * Debug mode: on
Address already in use
Port 5500 is in use by another program. Either identify and stop that program, or start the server with a different port.
 * Detected change in '/mnt/c/Users/Aryan/Desktop/m122_live_currency/Code/app.py', reloading
 * Restarting with stat
 * Debugger is active!
 * Debugger PIN: 100-709-659
 * Detected change in '/mnt/c/Users/Aryan/Desktop/m122_live_currency/Code/app.py', reloading
 * Restarting with stat
 * Debugger is active!
 * Debugger PIN: 100-709-659
 * Serving Flask app 'app'
 * Debug mode: on
Address already in use
Port 5500 is in use by another program. Either identify and stop that program, or start the server with a different port.
 * Detected change in '/mnt/c/Users/Aryan/Desktop/m122_live_currency/Code/app.py', reloading
 * Restarting with stat
 * Debugger is active!
 * Debugger PIN: 100-709-659
 * Detected change in '/mnt/c/Users/Aryan/Desktop/m122_live_currency/Code/app.py', reloading
 * Restarting with stat
 * Debugger is active!
 * Debugger PIN: 100-709-659
 * Detected change in '/mnt/c/Users/Aryan/Desktop/m122_live_currency/Code/app.py', reloading
 * Restarting with stat
 * Debugger is active!
 * Debugger PIN: 100-709-659
 * Detected change in '/mnt/c/Users/Aryan/Desktop/m122_live_currency/Code/app.py', reloading
 * Restarting with stat
 * Debugger is active!
 * Debugger PIN: 100-709-659
 * Detected change in '/mnt/c/Users/Aryan/Desktop/m122_live_currency/Code/app.py', reloading
 * Restarting with stat
 * Debugger is active!
 * Debugger PIN: 100-709-659
 * Detected change in '/mnt/c/Users/Aryan/Desktop/m122_live_currency/Code/app.py', reloading
 * Restarting with stat
  File "/mnt/c/Users/Aryan/Desktop/m122_live_currency/Code/app.py", line 27
    .json()['data']
    ^
SyntaxError: invalid syntax
 * Serving Flask app 'app'
 * Debug mode: on
[31m[1mWARNING: This is a development server. Do not use it in a production deployment. Use a production WSGI server instead.[0m
 * Running on http://127.0.0.1:5500
[33mPress CTRL+C to quit[0m
 * Restarting with stat
 * Debugger is active!
 * Debugger PIN: 100-709-659
127.0.0.1 - - [05/May/2024 15:54:10] "[35m[1mGET / HTTP/1.1[0m" 500 -
Traceback (most recent call last):
  File "/usr/local/lib/python3.10/dist-packages/flask/app.py", line 1498, in __call__
    return self.wsgi_app(environ, start_response)
  File "/usr/local/lib/python3.10/dist-packages/flask/app.py", line 1476, in wsgi_app
    response = self.handle_exception(e)
  File "/usr/local/lib/python3.10/dist-packages/flask/app.py", line 1473, in wsgi_app
    response = self.full_dispatch_request()
  File "/usr/local/lib/python3.10/dist-packages/flask/app.py", line 882, in full_dispatch_request
    rv = self.handle_user_exception(e)
  File "/usr/local/lib/python3.10/dist-packages/flask/app.py", line 880, in full_dispatch_request
    rv = self.dispatch_request()
  File "/usr/local/lib/python3.10/dist-packages/flask/app.py", line 865, in dispatch_request
    return self.ensure_sync(self.view_functions[rule.endpoint])(**view_args)  # type: ignore[no-any-return]
  File "/mnt/c/Users/Aryan/Desktop/m122_live_currency/Code/app.py", line 79, in home
    btc_price = cmc.getPrice('BTC')['data']['BTC']['quote']['USD']['price']
KeyError: 'data'
127.0.0.1 - - [05/May/2024 15:54:10] "[36mGET /?__debugger__=yes&cmd=resource&f=style.css HTTP/1.1[0m" 304 -
127.0.0.1 - - [05/May/2024 15:54:10] "[36mGET /?__debugger__=yes&cmd=resource&f=debugger.js HTTP/1.1[0m" 304 -
127.0.0.1 - - [05/May/2024 15:54:10] "[36mGET /?__debugger__=yes&cmd=resource&f=console.png HTTP/1.1[0m" 304 -
127.0.0.1 - - [05/May/2024 15:54:10] "[36mGET /?__debugger__=yes&cmd=resource&f=console.png HTTP/1.1[0m" 304 -
127.0.0.1 - - [05/May/2024 15:54:13] "[35m[1mGET / HTTP/1.1[0m" 500 -
Traceback (most recent call last):
  File "/usr/local/lib/python3.10/dist-packages/flask/app.py", line 1498, in __call__
    return self.wsgi_app(environ, start_response)
  File "/usr/local/lib/python3.10/dist-packages/flask/app.py", line 1476, in wsgi_app
    response = self.handle_exception(e)
  File "/usr/local/lib/python3.10/dist-packages/flask/app.py", line 1473, in wsgi_app
    response = self.full_dispatch_request()
  File "/usr/local/lib/python3.10/dist-packages/flask/app.py", line 882, in full_dispatch_request
    rv = self.handle_user_exception(e)
  File "/usr/local/lib/python3.10/dist-packages/flask/app.py", line 880, in full_dispatch_request
    rv = self.dispatch_request()
  File "/usr/local/lib/python3.10/dist-packages/flask/app.py", line 865, in dispatch_request
    return self.ensure_sync(self.view_functions[rule.endpoint])(**view_args)  # type: ignore[no-any-return]
  File "/mnt/c/Users/Aryan/Desktop/m122_live_currency/Code/app.py", line 79, in home
    btc_price = cmc.getPrice('BTC')['data']['BTC']['quote']['USD']['price']
KeyError: 'data'
127.0.0.1 - - [05/May/2024 15:54:13] "[36mGET /?__debugger__=yes&cmd=resource&f=style.css HTTP/1.1[0m" 304 -
127.0.0.1 - - [05/May/2024 15:54:13] "[36mGET /?__debugger__=yes&cmd=resource&f=debugger.js HTTP/1.1[0m" 304 -
127.0.0.1 - - [05/May/2024 15:54:13] "[36mGET /?__debugger__=yes&cmd=resource&f=console.png HTTP/1.1[0m" 304 -
127.0.0.1 - - [05/May/2024 15:54:13] "[36mGET /?__debugger__=yes&cmd=resource&f=console.png HTTP/1.1[0m" 304 -
127.0.0.1 - - [05/May/2024 15:54:31] "[35m[1mGET / HTTP/1.1[0m" 500 -
Traceback (most recent call last):
  File "/usr/local/lib/python3.10/dist-packages/flask/app.py", line 1498, in __call__
    return self.wsgi_app(environ, start_response)
  File "/usr/local/lib/python3.10/dist-packages/flask/app.py", line 1476, in wsgi_app
    response = self.handle_exception(e)
  File "/usr/local/lib/python3.10/dist-packages/flask/app.py", line 1473, in wsgi_app
    response = self.full_dispatch_request()
  File "/usr/local/lib/python3.10/dist-packages/flask/app.py", line 882, in full_dispatch_request
    rv = self.handle_user_exception(e)
  File "/usr/local/lib/python3.10/dist-packages/flask/app.py", line 880, in full_dispatch_request
    rv = self.dispatch_request()
  File "/usr/local/lib/python3.10/dist-packages/flask/app.py", line 865, in dispatch_request
    return self.ensure_sync(self.view_functions[rule.endpoint])(**view_args)  # type: ignore[no-any-return]
  File "/mnt/c/Users/Aryan/Desktop/m122_live_currency/Code/app.py", line 79, in home
    btc_price = cmc.getPrice('BTC')['data']['BTC']['quote']['USD']['price']
KeyError: 'data'
127.0.0.1 - - [05/May/2024 15:54:31] "[36mGET /?__debugger__=yes&cmd=resource&f=style.css HTTP/1.1[0m" 304 -
127.0.0.1 - - [05/May/2024 15:54:31] "[36mGET /?__debugger__=yes&cmd=resource&f=debugger.js HTTP/1.1[0m" 304 -
127.0.0.1 - - [05/May/2024 15:54:31] "[36mGET /?__debugger__=yes&cmd=resource&f=console.png HTTP/1.1[0m" 304 -
127.0.0.1 - - [05/May/2024 15:54:31] "[36mGET /?__debugger__=yes&cmd=resource&f=console.png HTTP/1.1[0m" 304 -
127.0.0.1 - - [05/May/2024 15:54:35] "[35m[1mGET / HTTP/1.1[0m" 500 -
Traceback (most recent call last):
  File "/usr/local/lib/python3.10/dist-packages/flask/app.py", line 1498, in __call__
    return self.wsgi_app(environ, start_response)
  File "/usr/local/lib/python3.10/dist-packages/flask/app.py", line 1476, in wsgi_app
    response = self.handle_exception(e)
  File "/usr/local/lib/python3.10/dist-packages/flask/app.py", line 1473, in wsgi_app
    response = self.full_dispatch_request()
  File "/usr/local/lib/python3.10/dist-packages/flask/app.py", line 882, in full_dispatch_request
    rv = self.handle_user_exception(e)
  File "/usr/local/lib/python3.10/dist-packages/flask/app.py", line 880, in full_dispatch_request
    rv = self.dispatch_request()
  File "/usr/local/lib/python3.10/dist-packages/flask/app.py", line 865, in dispatch_request
    return self.ensure_sync(self.view_functions[rule.endpoint])(**view_args)  # type: ignore[no-any-return]
  File "/mnt/c/Users/Aryan/Desktop/m122_live_currency/Code/app.py", line 79, in home
    btc_price = cmc.getPrice('BTC')['data']['BTC']['quote']['USD']['price']
KeyError: 'data'
127.0.0.1 - - [05/May/2024 15:54:35] "[36mGET /?__debugger__=yes&cmd=resource&f=style.css HTTP/1.1[0m" 304 -
127.0.0.1 - - [05/May/2024 15:54:35] "[36mGET /?__debugger__=yes&cmd=resource&f=debugger.js HTTP/1.1[0m" 304 -
127.0.0.1 - - [05/May/2024 15:54:35] "[36mGET /?__debugger__=yes&cmd=resource&f=console.png HTTP/1.1[0m" 304 -
127.0.0.1 - - [05/May/2024 15:54:35] "[36mGET /?__debugger__=yes&cmd=resource&f=console.png HTTP/1.1[0m" 304 -
 * Serving Flask app 'app'
 * Debug mode: on
Address already in use
Port 5500 is in use by another program. Either identify and stop that program, or start the server with a different port.
127.0.0.1 - - [05/May/2024 15:55:23] "[35m[1mGET / HTTP/1.1[0m" 500 -
Traceback (most recent call last):
  File "/usr/local/lib/python3.10/dist-packages/flask/app.py", line 1498, in __call__
    return self.wsgi_app(environ, start_response)
  File "/usr/local/lib/python3.10/dist-packages/flask/app.py", line 1476, in wsgi_app
    response = self.handle_exception(e)
  File "/usr/local/lib/python3.10/dist-packages/flask/app.py", line 1473, in wsgi_app
    response = self.full_dispatch_request()
  File "/usr/local/lib/python3.10/dist-packages/flask/app.py", line 882, in full_dispatch_request
    rv = self.handle_user_exception(e)
  File "/usr/local/lib/python3.10/dist-packages/flask/app.py", line 880, in full_dispatch_request
    rv = self.dispatch_request()
  File "/usr/local/lib/python3.10/dist-packages/flask/app.py", line 865, in dispatch_request
    return self.ensure_sync(self.view_functions[rule.endpoint])(**view_args)  # type: ignore[no-any-return]
  File "/mnt/c/Users/Aryan/Desktop/m122_live_currency/Code/app.py", line 79, in home
    btc_price = cmc.getPrice('BTC')['data']['BTC']['quote']['USD']['price']
KeyError: 'data'
127.0.0.1 - - [05/May/2024 15:55:23] "[36mGET /?__debugger__=yes&cmd=resource&f=style.css HTTP/1.1[0m" 304 -
127.0.0.1 - - [05/May/2024 15:55:23] "[36mGET /?__debugger__=yes&cmd=resource&f=debugger.js HTTP/1.1[0m" 304 -
127.0.0.1 - - [05/May/2024 15:55:23] "[36mGET /?__debugger__=yes&cmd=resource&f=console.png HTTP/1.1[0m" 304 -
127.0.0.1 - - [05/May/2024 15:55:23] "[36mGET /?__debugger__=yes&cmd=resource&f=console.png HTTP/1.1[0m" 304 -
127.0.0.1 - - [05/May/2024 15:55:31] "[35m[1mGET / HTTP/1.1[0m" 500 -
Traceback (most recent call last):
  File "/usr/local/lib/python3.10/dist-packages/flask/app.py", line 1498, in __call__
    return self.wsgi_app(environ, start_response)
  File "/usr/local/lib/python3.10/dist-packages/flask/app.py", line 1476, in wsgi_app
    response = self.handle_exception(e)
  File "/usr/local/lib/python3.10/dist-packages/flask/app.py", line 1473, in wsgi_app
    response = self.full_dispatch_request()
  File "/usr/local/lib/python3.10/dist-packages/flask/app.py", line 882, in full_dispatch_request
    rv = self.handle_user_exception(e)
  File "/usr/local/lib/python3.10/dist-packages/flask/app.py", line 880, in full_dispatch_request
    rv = self.dispatch_request()
  File "/usr/local/lib/python3.10/dist-packages/flask/app.py", line 865, in dispatch_request
    return self.ensure_sync(self.view_functions[rule.endpoint])(**view_args)  # type: ignore[no-any-return]
  File "/mnt/c/Users/Aryan/Desktop/m122_live_currency/Code/app.py", line 79, in home
    btc_price = cmc.getPrice('BTC')['data']['BTC']['quote']['USD']['price']
KeyError: 'data'
127.0.0.1 - - [05/May/2024 15:55:32] "[36mGET /?__debugger__=yes&cmd=resource&f=style.css HTTP/1.1[0m" 304 -
127.0.0.1 - - [05/May/2024 15:55:32] "[36mGET /?__debugger__=yes&cmd=resource&f=debugger.js HTTP/1.1[0m" 304 -
127.0.0.1 - - [05/May/2024 15:55:32] "[36mGET /?__debugger__=yes&cmd=resource&f=console.png HTTP/1.1[0m" 304 -
 * Serving Flask app 'app'
 * Debug mode: on
Address already in use
Port 5500 is in use by another program. Either identify and stop that program, or start the server with a different port.
 * Detected change in '/mnt/c/Users/Aryan/Desktop/m122_live_currency/Code/app.py', reloading
 * Restarting with stat
 * Debugger is active!
 * Debugger PIN: 100-709-659
127.0.0.1 - - [05/May/2024 15:56:18] "[35m[1mGET / HTTP/1.1[0m" 500 -
Traceback (most recent call last):
  File "/usr/local/lib/python3.10/dist-packages/flask/app.py", line 1498, in __call__
    return self.wsgi_app(environ, start_response)
  File "/usr/local/lib/python3.10/dist-packages/flask/app.py", line 1476, in wsgi_app
    response = self.handle_exception(e)
  File "/usr/local/lib/python3.10/dist-packages/flask/app.py", line 1473, in wsgi_app
    response = self.full_dispatch_request()
  File "/usr/local/lib/python3.10/dist-packages/flask/app.py", line 882, in full_dispatch_request
    rv = self.handle_user_exception(e)
  File "/usr/local/lib/python3.10/dist-packages/flask/app.py", line 880, in full_dispatch_request
    rv = self.dispatch_request()
  File "/usr/local/lib/python3.10/dist-packages/flask/app.py", line 865, in dispatch_request
    return self.ensure_sync(self.view_functions[rule.endpoint])(**view_args)  # type: ignore[no-any-return]
  File "/mnt/c/Users/Aryan/Desktop/m122_live_currency/Code/app.py", line 79, in home
    btc_price = cmc.getPrice('BTC')['data']['BTC']['quote']['USD']['price']
KeyError: 'data'
127.0.0.1 - - [05/May/2024 15:56:18] "[36mGET /?__debugger__=yes&cmd=resource&f=style.css HTTP/1.1[0m" 304 -
127.0.0.1 - - [05/May/2024 15:56:18] "[36mGET /?__debugger__=yes&cmd=resource&f=debugger.js HTTP/1.1[0m" 304 -
127.0.0.1 - - [05/May/2024 15:56:18] "[36mGET /?__debugger__=yes&cmd=resource&f=console.png HTTP/1.1[0m" 304 -
127.0.0.1 - - [05/May/2024 15:56:18] "[36mGET /?__debugger__=yes&cmd=resource&f=console.png HTTP/1.1[0m" 304 -
 * Detected change in '/mnt/c/Users/Aryan/Desktop/m122_live_currency/Code/app.py', reloading
 * Restarting with stat
 * Debugger is active!
 * Debugger PIN: 100-709-659
 * Detected change in '/mnt/c/Users/Aryan/Desktop/m122_live_currency/Code/app.py', reloading
 * Restarting with stat
 * Debugger is active!
 * Debugger PIN: 100-709-659
 * Detected change in '/mnt/c/Users/Aryan/Desktop/m122_live_currency/Code/app.py', reloading
 * Restarting with stat
 * Debugger is active!
 * Debugger PIN: 100-709-659
127.0.0.1 - - [05/May/2024 15:56:39] "[35m[1mGET / HTTP/1.1[0m" 500 -
Traceback (most recent call last):
  File "/usr/local/lib/python3.10/dist-packages/flask/app.py", line 1498, in __call__
    return self.wsgi_app(environ, start_response)
  File "/usr/local/lib/python3.10/dist-packages/flask/app.py", line 1476, in wsgi_app
    response = self.handle_exception(e)
  File "/usr/local/lib/python3.10/dist-packages/flask/app.py", line 1473, in wsgi_app
    response = self.full_dispatch_request()
  File "/usr/local/lib/python3.10/dist-packages/flask/app.py", line 882, in full_dispatch_request
    rv = self.handle_user_exception(e)
  File "/usr/local/lib/python3.10/dist-packages/flask/app.py", line 880, in full_dispatch_request
    rv = self.dispatch_request()
  File "/usr/local/lib/python3.10/dist-packages/flask/app.py", line 865, in dispatch_request
    return self.ensure_sync(self.view_functions[rule.endpoint])(**view_args)  # type: ignore[no-any-return]
  File "/mnt/c/Users/Aryan/Desktop/m122_live_currency/Code/app.py", line 78, in home
    btc_price = cmc.getPrice('BTC')['data']['BTC']['quote']['USD']['price']
KeyError: 'data'
127.0.0.1 - - [05/May/2024 15:56:39] "[36mGET /?__debugger__=yes&cmd=resource&f=style.css HTTP/1.1[0m" 304 -
127.0.0.1 - - [05/May/2024 15:56:39] "[36mGET /?__debugger__=yes&cmd=resource&f=debugger.js HTTP/1.1[0m" 304 -
127.0.0.1 - - [05/May/2024 15:56:39] "[36mGET /?__debugger__=yes&cmd=resource&f=console.png HTTP/1.1[0m" 304 -
127.0.0.1 - - [05/May/2024 15:56:39] "[36mGET /?__debugger__=yes&cmd=resource&f=console.png HTTP/1.1[0m" 304 -
127.0.0.1 - - [05/May/2024 15:56:41] "[35m[1mGET / HTTP/1.1[0m" 500 -
Traceback (most recent call last):
  File "/usr/local/lib/python3.10/dist-packages/flask/app.py", line 1498, in __call__
    return self.wsgi_app(environ, start_response)
  File "/usr/local/lib/python3.10/dist-packages/flask/app.py", line 1476, in wsgi_app
    response = self.handle_exception(e)
  File "/usr/local/lib/python3.10/dist-packages/flask/app.py", line 1473, in wsgi_app
    response = self.full_dispatch_request()
  File "/usr/local/lib/python3.10/dist-packages/flask/app.py", line 882, in full_dispatch_request
    rv = self.handle_user_exception(e)
  File "/usr/local/lib/python3.10/dist-packages/flask/app.py", line 880, in full_dispatch_request
    rv = self.dispatch_request()
  File "/usr/local/lib/python3.10/dist-packages/flask/app.py", line 865, in dispatch_request
    return self.ensure_sync(self.view_functions[rule.endpoint])(**view_args)  # type: ignore[no-any-return]
  File "/mnt/c/Users/Aryan/Desktop/m122_live_currency/Code/app.py", line 78, in home
    btc_price = cmc.getPrice('BTC')['data']['BTC']['quote']['USD']['price']
KeyError: 'data'
127.0.0.1 - - [05/May/2024 15:56:41] "[36mGET /?__debugger__=yes&cmd=resource&f=style.css HTTP/1.1[0m" 304 -
127.0.0.1 - - [05/May/2024 15:56:41] "[36mGET /?__debugger__=yes&cmd=resource&f=debugger.js HTTP/1.1[0m" 304 -
127.0.0.1 - - [05/May/2024 15:56:41] "[36mGET /?__debugger__=yes&cmd=resource&f=console.png HTTP/1.1[0m" 304 -
127.0.0.1 - - [05/May/2024 15:56:41] "[36mGET /?__debugger__=yes&cmd=resource&f=console.png HTTP/1.1[0m" 304 -
 * Detected change in '/mnt/c/Users/Aryan/Desktop/m122_live_currency/Code/app.py', reloading
 * Restarting with stat
 * Debugger is active!
 * Debugger PIN: 100-709-659
 * Serving Flask app 'app'
 * Debug mode: on
Address already in use
Port 5500 is in use by another program. Either identify and stop that program, or start the server with a different port.
127.0.0.1 - - [05/May/2024 15:57:03] "[35m[1mGET / HTTP/1.1[0m" 500 -
Traceback (most recent call last):
  File "/usr/local/lib/python3.10/dist-packages/flask/app.py", line 1498, in __call__
    return self.wsgi_app(environ, start_response)
  File "/usr/local/lib/python3.10/dist-packages/flask/app.py", line 1476, in wsgi_app
    response = self.handle_exception(e)
  File "/usr/local/lib/python3.10/dist-packages/flask/app.py", line 1473, in wsgi_app
    response = self.full_dispatch_request()
  File "/usr/local/lib/python3.10/dist-packages/flask/app.py", line 882, in full_dispatch_request
    rv = self.handle_user_exception(e)
  File "/usr/local/lib/python3.10/dist-packages/flask/app.py", line 880, in full_dispatch_request
    rv = self.dispatch_request()
  File "/usr/local/lib/python3.10/dist-packages/flask/app.py", line 865, in dispatch_request
    return self.ensure_sync(self.view_functions[rule.endpoint])(**view_args)  # type: ignore[no-any-return]
  File "/mnt/c/Users/Aryan/Desktop/m122_live_currency/Code/app.py", line 79, in home
    btc_price = cmc.getPrice('BTC')['data']['BTC']['quote']['USD']['price']
KeyError: 'data'
127.0.0.1 - - [05/May/2024 15:57:03] "[36mGET /?__debugger__=yes&cmd=resource&f=debugger.js HTTP/1.1[0m" 304 -
127.0.0.1 - - [05/May/2024 15:57:03] "[36mGET /?__debugger__=yes&cmd=resource&f=style.css HTTP/1.1[0m" 304 -
127.0.0.1 - - [05/May/2024 15:57:03] "[36mGET /?__debugger__=yes&cmd=resource&f=console.png HTTP/1.1[0m" 304 -
127.0.0.1 - - [05/May/2024 15:57:03] "[36mGET /?__debugger__=yes&cmd=resource&f=console.png HTTP/1.1[0m" 304 -
 * Detected change in '/mnt/c/Users/Aryan/Desktop/m122_live_currency/Code/app.py', reloading
 * Restarting with stat
 * Debugger is active!
 * Debugger PIN: 100-709-659
 * Detected change in '/mnt/c/Users/Aryan/Desktop/m122_live_currency/Code/app.py', reloading
 * Restarting with stat
 * Debugger is active!
 * Debugger PIN: 100-709-659
127.0.0.1 - - [05/May/2024 15:57:38] "[35m[1mGET / HTTP/1.1[0m" 500 -
Traceback (most recent call last):
  File "/usr/local/lib/python3.10/dist-packages/flask/app.py", line 1498, in __call__
    return self.wsgi_app(environ, start_response)
  File "/usr/local/lib/python3.10/dist-packages/flask/app.py", line 1476, in wsgi_app
    response = self.handle_exception(e)
  File "/usr/local/lib/python3.10/dist-packages/flask/app.py", line 1473, in wsgi_app
    response = self.full_dispatch_request()
  File "/usr/local/lib/python3.10/dist-packages/flask/app.py", line 882, in full_dispatch_request
    rv = self.handle_user_exception(e)
  File "/usr/local/lib/python3.10/dist-packages/flask/app.py", line 880, in full_dispatch_request
    rv = self.dispatch_request()
  File "/usr/local/lib/python3.10/dist-packages/flask/app.py", line 865, in dispatch_request
    return self.ensure_sync(self.view_functions[rule.endpoint])(**view_args)  # type: ignore[no-any-return]
  File "/mnt/c/Users/Aryan/Desktop/m122_live_currency/Code/app.py", line 79, in home
    btc_price = cmc.getPrice('BTC')['BTC']['quote']['USD']['price']
KeyError: 'BTC'
127.0.0.1 - - [05/May/2024 15:57:38] "[36mGET /?__debugger__=yes&cmd=resource&f=style.css HTTP/1.1[0m" 304 -
127.0.0.1 - - [05/May/2024 15:57:38] "[36mGET /?__debugger__=yes&cmd=resource&f=debugger.js HTTP/1.1[0m" 304 -
127.0.0.1 - - [05/May/2024 15:57:38] "[36mGET /?__debugger__=yes&cmd=resource&f=console.png HTTP/1.1[0m" 304 -
127.0.0.1 - - [05/May/2024 15:57:38] "[36mGET /?__debugger__=yes&cmd=resource&f=console.png HTTP/1.1[0m" 304 -
 * Detected change in '/mnt/c/Users/Aryan/Desktop/m122_live_currency/Code/app.py', reloading
 * Restarting with stat
 * Debugger is active!
 * Debugger PIN: 100-709-659
127.0.0.1 - - [05/May/2024 15:57:43] "[35m[1mGET / HTTP/1.1[0m" 500 -
Traceback (most recent call last):
  File "/usr/local/lib/python3.10/dist-packages/flask/app.py", line 1498, in __call__
    return self.wsgi_app(environ, start_response)
  File "/usr/local/lib/python3.10/dist-packages/flask/app.py", line 1476, in wsgi_app
    response = self.handle_exception(e)
  File "/usr/local/lib/python3.10/dist-packages/flask/app.py", line 1473, in wsgi_app
    response = self.full_dispatch_request()
  File "/usr/local/lib/python3.10/dist-packages/flask/app.py", line 882, in full_dispatch_request
    rv = self.handle_user_exception(e)
  File "/usr/local/lib/python3.10/dist-packages/flask/app.py", line 880, in full_dispatch_request
    rv = self.dispatch_request()
  File "/usr/local/lib/python3.10/dist-packages/flask/app.py", line 865, in dispatch_request
    return self.ensure_sync(self.view_functions[rule.endpoint])(**view_args)  # type: ignore[no-any-return]
  File "/mnt/c/Users/Aryan/Desktop/m122_live_currency/Code/app.py", line 79, in home
    btc_price = cmc.getPrice('BTC')['data']['BTC']['quote']['USD']['price']
KeyError: 'data'
127.0.0.1 - - [05/May/2024 15:57:43] "[36mGET /?__debugger__=yes&cmd=resource&f=style.css HTTP/1.1[0m" 304 -
127.0.0.1 - - [05/May/2024 15:57:43] "[36mGET /?__debugger__=yes&cmd=resource&f=debugger.js HTTP/1.1[0m" 304 -
127.0.0.1 - - [05/May/2024 15:57:43] "[36mGET /?__debugger__=yes&cmd=resource&f=console.png HTTP/1.1[0m" 304 -
127.0.0.1 - - [05/May/2024 15:57:43] "[36mGET /?__debugger__=yes&cmd=resource&f=console.png HTTP/1.1[0m" 304 -
 * Serving Flask app 'app'
 * Debug mode: on
Address already in use
Port 5500 is in use by another program. Either identify and stop that program, or start the server with a different port.
 * Serving Flask app 'app'
 * Debug mode: on
Address already in use
Port 5500 is in use by another program. Either identify and stop that program, or start the server with a different port.
 * Serving Flask app 'app'
 * Debug mode: on
Address already in use
Port 5500 is in use by another program. Either identify and stop that program, or start the server with a different port.
127.0.0.1 - - [05/May/2024 16:00:57] "[35m[1mGET / HTTP/1.1[0m" 500 -
Traceback (most recent call last):
  File "/usr/local/lib/python3.10/dist-packages/flask/app.py", line 1498, in __call__
    return self.wsgi_app(environ, start_response)
  File "/usr/local/lib/python3.10/dist-packages/flask/app.py", line 1476, in wsgi_app
    response = self.handle_exception(e)
  File "/usr/local/lib/python3.10/dist-packages/flask/app.py", line 1473, in wsgi_app
    response = self.full_dispatch_request()
  File "/usr/local/lib/python3.10/dist-packages/flask/app.py", line 882, in full_dispatch_request
    rv = self.handle_user_exception(e)
  File "/usr/local/lib/python3.10/dist-packages/flask/app.py", line 880, in full_dispatch_request
    rv = self.dispatch_request()
  File "/usr/local/lib/python3.10/dist-packages/flask/app.py", line 865, in dispatch_request
    return self.ensure_sync(self.view_functions[rule.endpoint])(**view_args)  # type: ignore[no-any-return]
  File "/mnt/c/Users/Aryan/Desktop/m122_live_currency/Code/app.py", line 79, in home
    btc_price = cmc.getPrice('BTC')['data']['BTC']['quote']['USD']['price']
KeyError: 'data'
127.0.0.1 - - [05/May/2024 16:00:57] "[36mGET /?__debugger__=yes&cmd=resource&f=style.css HTTP/1.1[0m" 304 -
127.0.0.1 - - [05/May/2024 16:00:57] "[36mGET /?__debugger__=yes&cmd=resource&f=debugger.js HTTP/1.1[0m" 304 -
127.0.0.1 - - [05/May/2024 16:00:57] "[36mGET /?__debugger__=yes&cmd=resource&f=console.png HTTP/1.1[0m" 304 -
127.0.0.1 - - [05/May/2024 16:00:57] "[36mGET /?__debugger__=yes&cmd=resource&f=console.png HTTP/1.1[0m" 304 -
127.0.0.1 - - [05/May/2024 16:01:00] "[35m[1mGET / HTTP/1.1[0m" 500 -
Traceback (most recent call last):
  File "/usr/local/lib/python3.10/dist-packages/flask/app.py", line 1498, in __call__
    return self.wsgi_app(environ, start_response)
  File "/usr/local/lib/python3.10/dist-packages/flask/app.py", line 1476, in wsgi_app
    response = self.handle_exception(e)
  File "/usr/local/lib/python3.10/dist-packages/flask/app.py", line 1473, in wsgi_app
    response = self.full_dispatch_request()
  File "/usr/local/lib/python3.10/dist-packages/flask/app.py", line 882, in full_dispatch_request
    rv = self.handle_user_exception(e)
  File "/usr/local/lib/python3.10/dist-packages/flask/app.py", line 880, in full_dispatch_request
    rv = self.dispatch_request()
  File "/usr/local/lib/python3.10/dist-packages/flask/app.py", line 865, in dispatch_request
    return self.ensure_sync(self.view_functions[rule.endpoint])(**view_args)  # type: ignore[no-any-return]
  File "/mnt/c/Users/Aryan/Desktop/m122_live_currency/Code/app.py", line 79, in home
    btc_price = cmc.getPrice('BTC')['data']['BTC']['quote']['USD']['price']
KeyError: 'data'
127.0.0.1 - - [05/May/2024 16:01:00] "[36mGET /?__debugger__=yes&cmd=resource&f=style.css HTTP/1.1[0m" 304 -
127.0.0.1 - - [05/May/2024 16:01:00] "[36mGET /?__debugger__=yes&cmd=resource&f=debugger.js HTTP/1.1[0m" 304 -
127.0.0.1 - - [05/May/2024 16:01:00] "[36mGET /?__debugger__=yes&cmd=resource&f=console.png HTTP/1.1[0m" 304 -
127.0.0.1 - - [05/May/2024 16:01:00] "[36mGET /?__debugger__=yes&cmd=resource&f=console.png HTTP/1.1[0m" 304 -
 * Serving Flask app 'app'
 * Debug mode: on
Address already in use
Port 5500 is in use by another program. Either identify and stop that program, or start the server with a different port.
127.0.0.1 - - [05/May/2024 16:01:02] "[35m[1mGET / HTTP/1.1[0m" 500 -
Traceback (most recent call last):
  File "/usr/local/lib/python3.10/dist-packages/flask/app.py", line 1498, in __call__
    return self.wsgi_app(environ, start_response)
  File "/usr/local/lib/python3.10/dist-packages/flask/app.py", line 1476, in wsgi_app
    response = self.handle_exception(e)
  File "/usr/local/lib/python3.10/dist-packages/flask/app.py", line 1473, in wsgi_app
    response = self.full_dispatch_request()
  File "/usr/local/lib/python3.10/dist-packages/flask/app.py", line 882, in full_dispatch_request
    rv = self.handle_user_exception(e)
  File "/usr/local/lib/python3.10/dist-packages/flask/app.py", line 880, in full_dispatch_request
    rv = self.dispatch_request()
  File "/usr/local/lib/python3.10/dist-packages/flask/app.py", line 865, in dispatch_request
    return self.ensure_sync(self.view_functions[rule.endpoint])(**view_args)  # type: ignore[no-any-return]
  File "/mnt/c/Users/Aryan/Desktop/m122_live_currency/Code/app.py", line 79, in home
    btc_price = cmc.getPrice('BTC')['data']['BTC']['quote']['USD']['price']
KeyError: 'data'
127.0.0.1 - - [05/May/2024 16:01:02] "[36mGET /?__debugger__=yes&cmd=resource&f=style.css HTTP/1.1[0m" 304 -
127.0.0.1 - - [05/May/2024 16:01:02] "[36mGET /?__debugger__=yes&cmd=resource&f=debugger.js HTTP/1.1[0m" 304 -
127.0.0.1 - - [05/May/2024 16:01:02] "[36mGET /?__debugger__=yes&cmd=resource&f=console.png HTTP/1.1[0m" 304 -
127.0.0.1 - - [05/May/2024 16:01:02] "[36mGET /?__debugger__=yes&cmd=resource&f=console.png HTTP/1.1[0m" 304 -
127.0.0.1 - - [05/May/2024 16:01:16] "[35m[1mGET / HTTP/1.1[0m" 500 -
Traceback (most recent call last):
  File "/usr/local/lib/python3.10/dist-packages/flask/app.py", line 1498, in __call__
    return self.wsgi_app(environ, start_response)
  File "/usr/local/lib/python3.10/dist-packages/flask/app.py", line 1476, in wsgi_app
    response = self.handle_exception(e)
  File "/usr/local/lib/python3.10/dist-packages/flask/app.py", line 1473, in wsgi_app
    response = self.full_dispatch_request()
  File "/usr/local/lib/python3.10/dist-packages/flask/app.py", line 882, in full_dispatch_request
    rv = self.handle_user_exception(e)
  File "/usr/local/lib/python3.10/dist-packages/flask/app.py", line 880, in full_dispatch_request
    rv = self.dispatch_request()
  File "/usr/local/lib/python3.10/dist-packages/flask/app.py", line 865, in dispatch_request
    return self.ensure_sync(self.view_functions[rule.endpoint])(**view_args)  # type: ignore[no-any-return]
  File "/mnt/c/Users/Aryan/Desktop/m122_live_currency/Code/app.py", line 79, in home
    btc_price = cmc.getPrice('BTC')['data']['BTC']['quote']['USD']['price']
KeyError: 'data'
127.0.0.1 - - [05/May/2024 16:01:16] "[36mGET /?__debugger__=yes&cmd=resource&f=style.css HTTP/1.1[0m" 304 -
127.0.0.1 - - [05/May/2024 16:01:16] "[36mGET /?__debugger__=yes&cmd=resource&f=debugger.js HTTP/1.1[0m" 304 -
127.0.0.1 - - [05/May/2024 16:01:16] "[36mGET /?__debugger__=yes&cmd=resource&f=console.png HTTP/1.1[0m" 304 -
127.0.0.1 - - [05/May/2024 16:01:17] "[35m[1mGET / HTTP/1.1[0m" 500 -
Traceback (most recent call last):
  File "/usr/local/lib/python3.10/dist-packages/flask/app.py", line 1498, in __call__
    return self.wsgi_app(environ, start_response)
  File "/usr/local/lib/python3.10/dist-packages/flask/app.py", line 1476, in wsgi_app
    response = self.handle_exception(e)
  File "/usr/local/lib/python3.10/dist-packages/flask/app.py", line 1473, in wsgi_app
    response = self.full_dispatch_request()
  File "/usr/local/lib/python3.10/dist-packages/flask/app.py", line 882, in full_dispatch_request
    rv = self.handle_user_exception(e)
  File "/usr/local/lib/python3.10/dist-packages/flask/app.py", line 880, in full_dispatch_request
    rv = self.dispatch_request()
  File "/usr/local/lib/python3.10/dist-packages/flask/app.py", line 865, in dispatch_request
    return self.ensure_sync(self.view_functions[rule.endpoint])(**view_args)  # type: ignore[no-any-return]
  File "/mnt/c/Users/Aryan/Desktop/m122_live_currency/Code/app.py", line 79, in home
    btc_price = cmc.getPrice('BTC')['data']['BTC']['quote']['USD']['price']
KeyError: 'data'
127.0.0.1 - - [05/May/2024 16:01:17] "[36mGET /?__debugger__=yes&cmd=resource&f=style.css HTTP/1.1[0m" 304 -
127.0.0.1 - - [05/May/2024 16:01:17] "[36mGET /?__debugger__=yes&cmd=resource&f=debugger.js HTTP/1.1[0m" 304 -
127.0.0.1 - - [05/May/2024 16:01:17] "[36mGET /?__debugger__=yes&cmd=resource&f=console.png HTTP/1.1[0m" 304 -
 * Serving Flask app 'app'
 * Debug mode: on
Address already in use
Port 5500 is in use by another program. Either identify and stop that program, or start the server with a different port.
 * Serving Flask app 'app'
 * Debug mode: on
Address already in use
Port 5500 is in use by another program. Either identify and stop that program, or start the server with a different port.
127.0.0.1 - - [05/May/2024 16:03:51] "[35m[1mGET / HTTP/1.1[0m" 500 -
Traceback (most recent call last):
  File "/usr/local/lib/python3.10/dist-packages/flask/app.py", line 1498, in __call__
    return self.wsgi_app(environ, start_response)
  File "/usr/local/lib/python3.10/dist-packages/flask/app.py", line 1476, in wsgi_app
    response = self.handle_exception(e)
  File "/usr/local/lib/python3.10/dist-packages/flask/app.py", line 1473, in wsgi_app
    response = self.full_dispatch_request()
  File "/usr/local/lib/python3.10/dist-packages/flask/app.py", line 882, in full_dispatch_request
    rv = self.handle_user_exception(e)
  File "/usr/local/lib/python3.10/dist-packages/flask/app.py", line 880, in full_dispatch_request
    rv = self.dispatch_request()
  File "/usr/local/lib/python3.10/dist-packages/flask/app.py", line 865, in dispatch_request
    return self.ensure_sync(self.view_functions[rule.endpoint])(**view_args)  # type: ignore[no-any-return]
  File "/mnt/c/Users/Aryan/Desktop/m122_live_currency/Code/app.py", line 79, in home
    btc_price = cmc.getPrice('BTC')['data']['BTC']['quote']['USD']['price']
KeyError: 'data'
127.0.0.1 - - [05/May/2024 16:03:51] "[36mGET /?__debugger__=yes&cmd=resource&f=style.css HTTP/1.1[0m" 304 -
127.0.0.1 - - [05/May/2024 16:03:51] "[36mGET /?__debugger__=yes&cmd=resource&f=debugger.js HTTP/1.1[0m" 304 -
127.0.0.1 - - [05/May/2024 16:03:52] "[36mGET /?__debugger__=yes&cmd=resource&f=console.png HTTP/1.1[0m" 304 -
127.0.0.1 - - [05/May/2024 16:03:52] "[36mGET /?__debugger__=yes&cmd=resource&f=console.png HTTP/1.1[0m" 304 -
127.0.0.1 - - [05/May/2024 16:04:06] "[35m[1mGET / HTTP/1.1[0m" 500 -
Traceback (most recent call last):
  File "/usr/local/lib/python3.10/dist-packages/flask/app.py", line 1498, in __call__
    return self.wsgi_app(environ, start_response)
  File "/usr/local/lib/python3.10/dist-packages/flask/app.py", line 1476, in wsgi_app
    response = self.handle_exception(e)
  File "/usr/local/lib/python3.10/dist-packages/flask/app.py", line 1473, in wsgi_app
    response = self.full_dispatch_request()
  File "/usr/local/lib/python3.10/dist-packages/flask/app.py", line 882, in full_dispatch_request
    rv = self.handle_user_exception(e)
  File "/usr/local/lib/python3.10/dist-packages/flask/app.py", line 880, in full_dispatch_request
    rv = self.dispatch_request()
  File "/usr/local/lib/python3.10/dist-packages/flask/app.py", line 865, in dispatch_request
    return self.ensure_sync(self.view_functions[rule.endpoint])(**view_args)  # type: ignore[no-any-return]
  File "/mnt/c/Users/Aryan/Desktop/m122_live_currency/Code/app.py", line 79, in home
    btc_price = cmc.getPrice('BTC')['data']['BTC']['quote']['USD']['price']
KeyError: 'data'
127.0.0.1 - - [05/May/2024 16:04:06] "[36mGET /?__debugger__=yes&cmd=resource&f=style.css HTTP/1.1[0m" 304 -
127.0.0.1 - - [05/May/2024 16:04:06] "[36mGET /?__debugger__=yes&cmd=resource&f=debugger.js HTTP/1.1[0m" 304 -
127.0.0.1 - - [05/May/2024 16:04:06] "[36mGET /?__debugger__=yes&cmd=resource&f=console.png HTTP/1.1[0m" 304 -
127.0.0.1 - - [05/May/2024 16:04:06] "[36mGET /?__debugger__=yes&cmd=resource&f=console.png HTTP/1.1[0m" 304 -
127.0.0.1 - - [05/May/2024 16:05:04] "[35m[1mGET / HTTP/1.1[0m" 500 -
Traceback (most recent call last):
  File "/usr/local/lib/python3.10/dist-packages/flask/app.py", line 1498, in __call__
    return self.wsgi_app(environ, start_response)
  File "/usr/local/lib/python3.10/dist-packages/flask/app.py", line 1476, in wsgi_app
    response = self.handle_exception(e)
  File "/usr/local/lib/python3.10/dist-packages/flask/app.py", line 1473, in wsgi_app
    response = self.full_dispatch_request()
  File "/usr/local/lib/python3.10/dist-packages/flask/app.py", line 882, in full_dispatch_request
    rv = self.handle_user_exception(e)
  File "/usr/local/lib/python3.10/dist-packages/flask/app.py", line 880, in full_dispatch_request
    rv = self.dispatch_request()
  File "/usr/local/lib/python3.10/dist-packages/flask/app.py", line 865, in dispatch_request
    return self.ensure_sync(self.view_functions[rule.endpoint])(**view_args)  # type: ignore[no-any-return]
  File "/mnt/c/Users/Aryan/Desktop/m122_live_currency/Code/app.py", line 79, in home
    btc_price = cmc.getPrice('BTC')['data']['BTC']['quote']['USD']['price']
KeyError: 'data'
127.0.0.1 - - [05/May/2024 16:05:04] "[36mGET /?__debugger__=yes&cmd=resource&f=style.css HTTP/1.1[0m" 304 -
127.0.0.1 - - [05/May/2024 16:05:04] "[36mGET /?__debugger__=yes&cmd=resource&f=debugger.js HTTP/1.1[0m" 304 -
127.0.0.1 - - [05/May/2024 16:05:04] "[36mGET /?__debugger__=yes&cmd=resource&f=console.png HTTP/1.1[0m" 304 -
127.0.0.1 - - [05/May/2024 16:05:04] "[36mGET /?__debugger__=yes&cmd=resource&f=console.png HTTP/1.1[0m" 304 -
127.0.0.1 - - [05/May/2024 16:05:20] "[35m[1mGET / HTTP/1.1[0m" 500 -
Traceback (most recent call last):
  File "/usr/local/lib/python3.10/dist-packages/flask/app.py", line 1498, in __call__
    return self.wsgi_app(environ, start_response)
  File "/usr/local/lib/python3.10/dist-packages/flask/app.py", line 1476, in wsgi_app
    response = self.handle_exception(e)
  File "/usr/local/lib/python3.10/dist-packages/flask/app.py", line 1473, in wsgi_app
    response = self.full_dispatch_request()
  File "/usr/local/lib/python3.10/dist-packages/flask/app.py", line 882, in full_dispatch_request
    rv = self.handle_user_exception(e)
  File "/usr/local/lib/python3.10/dist-packages/flask/app.py", line 880, in full_dispatch_request
    rv = self.dispatch_request()
  File "/usr/local/lib/python3.10/dist-packages/flask/app.py", line 865, in dispatch_request
    return self.ensure_sync(self.view_functions[rule.endpoint])(**view_args)  # type: ignore[no-any-return]
  File "/mnt/c/Users/Aryan/Desktop/m122_live_currency/Code/app.py", line 79, in home
    btc_price = cmc.getPrice('BTC')['data']['BTC']['quote']['USD']['price']
KeyError: 'data'
127.0.0.1 - - [05/May/2024 16:05:20] "[36mGET /?__debugger__=yes&cmd=resource&f=style.css HTTP/1.1[0m" 304 -
127.0.0.1 - - [05/May/2024 16:05:20] "[36mGET /?__debugger__=yes&cmd=resource&f=debugger.js HTTP/1.1[0m" 304 -
127.0.0.1 - - [05/May/2024 16:05:20] "[36mGET /?__debugger__=yes&cmd=resource&f=console.png HTTP/1.1[0m" 304 -
127.0.0.1 - - [05/May/2024 16:05:20] "[36mGET /?__debugger__=yes&cmd=resource&f=console.png HTTP/1.1[0m" 304 -
127.0.0.1 - - [05/May/2024 16:05:28] "[35m[1mGET / HTTP/1.1[0m" 500 -
Traceback (most recent call last):
  File "/usr/local/lib/python3.10/dist-packages/flask/app.py", line 1498, in __call__
    return self.wsgi_app(environ, start_response)
  File "/usr/local/lib/python3.10/dist-packages/flask/app.py", line 1476, in wsgi_app
    response = self.handle_exception(e)
  File "/usr/local/lib/python3.10/dist-packages/flask/app.py", line 1473, in wsgi_app
    response = self.full_dispatch_request()
  File "/usr/local/lib/python3.10/dist-packages/flask/app.py", line 882, in full_dispatch_request
    rv = self.handle_user_exception(e)
  File "/usr/local/lib/python3.10/dist-packages/flask/app.py", line 880, in full_dispatch_request
    rv = self.dispatch_request()
  File "/usr/local/lib/python3.10/dist-packages/flask/app.py", line 865, in dispatch_request
    return self.ensure_sync(self.view_functions[rule.endpoint])(**view_args)  # type: ignore[no-any-return]
  File "/mnt/c/Users/Aryan/Desktop/m122_live_currency/Code/app.py", line 79, in home
    btc_price = cmc.getPrice('BTC')['data']['BTC']['quote']['USD']['price']
KeyError: 'data'
127.0.0.1 - - [05/May/2024 16:05:28] "[36mGET /?__debugger__=yes&cmd=resource&f=debugger.js HTTP/1.1[0m" 304 -
127.0.0.1 - - [05/May/2024 16:05:28] "[36mGET /?__debugger__=yes&cmd=resource&f=style.css HTTP/1.1[0m" 304 -
127.0.0.1 - - [05/May/2024 16:05:28] "[36mGET /?__debugger__=yes&cmd=resource&f=console.png HTTP/1.1[0m" 304 -
127.0.0.1 - - [05/May/2024 16:05:29] "[36mGET /?__debugger__=yes&cmd=resource&f=console.png HTTP/1.1[0m" 304 -
127.0.0.1 - - [05/May/2024 16:05:30] "[35m[1mGET / HTTP/1.1[0m" 500 -
Traceback (most recent call last):
  File "/usr/local/lib/python3.10/dist-packages/flask/app.py", line 1498, in __call__
    return self.wsgi_app(environ, start_response)
  File "/usr/local/lib/python3.10/dist-packages/flask/app.py", line 1476, in wsgi_app
    response = self.handle_exception(e)
  File "/usr/local/lib/python3.10/dist-packages/flask/app.py", line 1473, in wsgi_app
    response = self.full_dispatch_request()
  File "/usr/local/lib/python3.10/dist-packages/flask/app.py", line 882, in full_dispatch_request
    rv = self.handle_user_exception(e)
  File "/usr/local/lib/python3.10/dist-packages/flask/app.py", line 880, in full_dispatch_request
    rv = self.dispatch_request()
  File "/usr/local/lib/python3.10/dist-packages/flask/app.py", line 865, in dispatch_request
    return self.ensure_sync(self.view_functions[rule.endpoint])(**view_args)  # type: ignore[no-any-return]
  File "/mnt/c/Users/Aryan/Desktop/m122_live_currency/Code/app.py", line 79, in home
    btc_price = cmc.getPrice('BTC')['data']['BTC']['quote']['USD']['price']
KeyError: 'data'
127.0.0.1 - - [05/May/2024 16:05:30] "[36mGET /?__debugger__=yes&cmd=resource&f=debugger.js HTTP/1.1[0m" 304 -
127.0.0.1 - - [05/May/2024 16:05:30] "[36mGET /?__debugger__=yes&cmd=resource&f=style.css HTTP/1.1[0m" 304 -
127.0.0.1 - - [05/May/2024 16:05:30] "[36mGET /?__debugger__=yes&cmd=resource&f=console.png HTTP/1.1[0m" 304 -
127.0.0.1 - - [05/May/2024 16:05:30] "[36mGET /?__debugger__=yes&cmd=resource&f=console.png HTTP/1.1[0m" 304 -
127.0.0.1 - - [05/May/2024 16:05:31] "[35m[1mGET / HTTP/1.1[0m" 500 -
Traceback (most recent call last):
  File "/usr/local/lib/python3.10/dist-packages/flask/app.py", line 1498, in __call__
    return self.wsgi_app(environ, start_response)
  File "/usr/local/lib/python3.10/dist-packages/flask/app.py", line 1476, in wsgi_app
    response = self.handle_exception(e)
  File "/usr/local/lib/python3.10/dist-packages/flask/app.py", line 1473, in wsgi_app
    response = self.full_dispatch_request()
  File "/usr/local/lib/python3.10/dist-packages/flask/app.py", line 882, in full_dispatch_request
    rv = self.handle_user_exception(e)
  File "/usr/local/lib/python3.10/dist-packages/flask/app.py", line 880, in full_dispatch_request
    rv = self.dispatch_request()
  File "/usr/local/lib/python3.10/dist-packages/flask/app.py", line 865, in dispatch_request
    return self.ensure_sync(self.view_functions[rule.endpoint])(**view_args)  # type: ignore[no-any-return]
  File "/mnt/c/Users/Aryan/Desktop/m122_live_currency/Code/app.py", line 79, in home
    btc_price = cmc.getPrice('BTC')['data']['BTC']['quote']['USD']['price']
KeyError: 'data'
127.0.0.1 - - [05/May/2024 16:05:31] "[36mGET /?__debugger__=yes&cmd=resource&f=style.css HTTP/1.1[0m" 304 -
127.0.0.1 - - [05/May/2024 16:05:31] "[36mGET /?__debugger__=yes&cmd=resource&f=debugger.js HTTP/1.1[0m" 304 -
127.0.0.1 - - [05/May/2024 16:05:31] "[36mGET /?__debugger__=yes&cmd=resource&f=console.png HTTP/1.1[0m" 304 -
127.0.0.1 - - [05/May/2024 16:05:31] "[36mGET /?__debugger__=yes&cmd=resource&f=console.png HTTP/1.1[0m" 304 -
127.0.0.1 - - [05/May/2024 16:05:33] "[35m[1mGET / HTTP/1.1[0m" 500 -
Traceback (most recent call last):
  File "/usr/local/lib/python3.10/dist-packages/flask/app.py", line 1498, in __call__
    return self.wsgi_app(environ, start_response)
  File "/usr/local/lib/python3.10/dist-packages/flask/app.py", line 1476, in wsgi_app
    response = self.handle_exception(e)
  File "/usr/local/lib/python3.10/dist-packages/flask/app.py", line 1473, in wsgi_app
    response = self.full_dispatch_request()
  File "/usr/local/lib/python3.10/dist-packages/flask/app.py", line 882, in full_dispatch_request
    rv = self.handle_user_exception(e)
  File "/usr/local/lib/python3.10/dist-packages/flask/app.py", line 880, in full_dispatch_request
    rv = self.dispatch_request()
  File "/usr/local/lib/python3.10/dist-packages/flask/app.py", line 865, in dispatch_request
    return self.ensure_sync(self.view_functions[rule.endpoint])(**view_args)  # type: ignore[no-any-return]
  File "/mnt/c/Users/Aryan/Desktop/m122_live_currency/Code/app.py", line 79, in home
    btc_price = cmc.getPrice('BTC')['data']['BTC']['quote']['USD']['price']
KeyError: 'data'
127.0.0.1 - - [05/May/2024 16:05:33] "[36mGET /?__debugger__=yes&cmd=resource&f=style.css HTTP/1.1[0m" 304 -
127.0.0.1 - - [05/May/2024 16:05:33] "[36mGET /?__debugger__=yes&cmd=resource&f=debugger.js HTTP/1.1[0m" 304 -
127.0.0.1 - - [05/May/2024 16:05:33] "[36mGET /?__debugger__=yes&cmd=resource&f=console.png HTTP/1.1[0m" 304 -
127.0.0.1 - - [05/May/2024 16:05:33] "[36mGET /?__debugger__=yes&cmd=resource&f=console.png HTTP/1.1[0m" 304 -
127.0.0.1 - - [05/May/2024 16:06:05] "[35m[1mGET / HTTP/1.1[0m" 500 -
Traceback (most recent call last):
  File "/usr/local/lib/python3.10/dist-packages/flask/app.py", line 1498, in __call__
    return self.wsgi_app(environ, start_response)
  File "/usr/local/lib/python3.10/dist-packages/flask/app.py", line 1476, in wsgi_app
    response = self.handle_exception(e)
  File "/usr/local/lib/python3.10/dist-packages/flask/app.py", line 1473, in wsgi_app
    response = self.full_dispatch_request()
  File "/usr/local/lib/python3.10/dist-packages/flask/app.py", line 882, in full_dispatch_request
    rv = self.handle_user_exception(e)
  File "/usr/local/lib/python3.10/dist-packages/flask/app.py", line 880, in full_dispatch_request
    rv = self.dispatch_request()
  File "/usr/local/lib/python3.10/dist-packages/flask/app.py", line 865, in dispatch_request
    return self.ensure_sync(self.view_functions[rule.endpoint])(**view_args)  # type: ignore[no-any-return]
  File "/mnt/c/Users/Aryan/Desktop/m122_live_currency/Code/app.py", line 79, in home
    btc_price = cmc.getPrice('BTC')['data']['BTC']['quote']['USD']['price']
KeyError: 'data'
127.0.0.1 - - [05/May/2024 16:06:05] "[36mGET /?__debugger__=yes&cmd=resource&f=debugger.js HTTP/1.1[0m" 304 -
127.0.0.1 - - [05/May/2024 16:06:05] "[36mGET /?__debugger__=yes&cmd=resource&f=style.css HTTP/1.1[0m" 304 -
127.0.0.1 - - [05/May/2024 16:06:05] "[36mGET /?__debugger__=yes&cmd=resource&f=console.png HTTP/1.1[0m" 304 -
127.0.0.1 - - [05/May/2024 16:06:05] "[36mGET /?__debugger__=yes&cmd=resource&f=console.png HTTP/1.1[0m" 304 -
127.0.0.1 - - [05/May/2024 16:08:01] "[35m[1mGET / HTTP/1.1[0m" 500 -
Traceback (most recent call last):
  File "/usr/local/lib/python3.10/dist-packages/urllib3/connectionpool.py", line 793, in urlopen
    response = self._make_request(
  File "/usr/local/lib/python3.10/dist-packages/urllib3/connectionpool.py", line 537, in _make_request
    response = conn.getresponse()
  File "/usr/local/lib/python3.10/dist-packages/urllib3/connection.py", line 466, in getresponse
    httplib_response = super().getresponse()
  File "/usr/lib/python3.10/http/client.py", line 1375, in getresponse
    response.begin()
  File "/usr/lib/python3.10/http/client.py", line 318, in begin
    version, status, reason = self._read_status()
  File "/usr/lib/python3.10/http/client.py", line 287, in _read_status
    raise RemoteDisconnected("Remote end closed connection without"
http.client.RemoteDisconnected: Remote end closed connection without response

During handling of the above exception, another exception occurred:

Traceback (most recent call last):
  File "/usr/local/lib/python3.10/dist-packages/requests/adapters.py", line 486, in send
    resp = conn.urlopen(
  File "/usr/local/lib/python3.10/dist-packages/urllib3/connectionpool.py", line 847, in urlopen
    retries = retries.increment(
  File "/usr/local/lib/python3.10/dist-packages/urllib3/util/retry.py", line 470, in increment
    raise reraise(type(error), error, _stacktrace)
  File "/usr/local/lib/python3.10/dist-packages/urllib3/util/util.py", line 38, in reraise
    raise value.with_traceback(tb)
  File "/usr/local/lib/python3.10/dist-packages/urllib3/connectionpool.py", line 793, in urlopen
    response = self._make_request(
  File "/usr/local/lib/python3.10/dist-packages/urllib3/connectionpool.py", line 537, in _make_request
    response = conn.getresponse()
  File "/usr/local/lib/python3.10/dist-packages/urllib3/connection.py", line 466, in getresponse
    httplib_response = super().getresponse()
  File "/usr/lib/python3.10/http/client.py", line 1375, in getresponse
    response.begin()
  File "/usr/lib/python3.10/http/client.py", line 318, in begin
    version, status, reason = self._read_status()
  File "/usr/lib/python3.10/http/client.py", line 287, in _read_status
    raise RemoteDisconnected("Remote end closed connection without"
urllib3.exceptions.ProtocolError: ('Connection aborted.', RemoteDisconnected('Remote end closed connection without response'))

During handling of the above exception, another exception occurred:

Traceback (most recent call last):
  File "/usr/local/lib/python3.10/dist-packages/flask/app.py", line 1498, in __call__
    return self.wsgi_app(environ, start_response)
  File "/usr/local/lib/python3.10/dist-packages/flask/app.py", line 1476, in wsgi_app
    response = self.handle_exception(e)
  File "/usr/local/lib/python3.10/dist-packages/flask/app.py", line 1473, in wsgi_app
    response = self.full_dispatch_request()
  File "/usr/local/lib/python3.10/dist-packages/flask/app.py", line 882, in full_dispatch_request
    rv = self.handle_user_exception(e)
  File "/usr/local/lib/python3.10/dist-packages/flask/app.py", line 880, in full_dispatch_request
    rv = self.dispatch_request()
  File "/usr/local/lib/python3.10/dist-packages/flask/app.py", line 865, in dispatch_request
    return self.ensure_sync(self.view_functions[rule.endpoint])(**view_args)  # type: ignore[no-any-return]
  File "/mnt/c/Users/Aryan/Desktop/m122_live_currency/Code/app.py", line 79, in home
    btc_price = cmc.getPrice('BTC')['data']['BTC']['quote']['USD']['price']
  File "/mnt/c/Users/Aryan/Desktop/m122_live_currency/Code/app.py", line 48, in getPrice
    response = self.session.get(url, params=parameters)
  File "/usr/local/lib/python3.10/dist-packages/requests/sessions.py", line 602, in get
    return self.request("GET", url, **kwargs)
  File "/usr/local/lib/python3.10/dist-packages/requests/sessions.py", line 589, in request
    resp = self.send(prep, **send_kwargs)
  File "/usr/local/lib/python3.10/dist-packages/requests/sessions.py", line 703, in send
    r = adapter.send(request, **kwargs)
  File "/usr/local/lib/python3.10/dist-packages/requests/adapters.py", line 501, in send
    raise ConnectionError(err, request=request)
requests.exceptions.ConnectionError: ('Connection aborted.', RemoteDisconnected('Remote end closed connection without response'))
127.0.0.1 - - [05/May/2024 16:08:01] "[36mGET /?__debugger__=yes&cmd=resource&f=debugger.js HTTP/1.1[0m" 304 -
127.0.0.1 - - [05/May/2024 16:08:01] "[36mGET /?__debugger__=yes&cmd=resource&f=style.css HTTP/1.1[0m" 304 -
127.0.0.1 - - [05/May/2024 16:08:01] "[36mGET /?__debugger__=yes&cmd=resource&f=console.png HTTP/1.1[0m" 304 -
127.0.0.1 - - [05/May/2024 16:08:01] "[36mGET /?__debugger__=yes&cmd=resource&f=console.png HTTP/1.1[0m" 304 -
127.0.0.1 - - [05/May/2024 16:08:08] "[35m[1mGET / HTTP/1.1[0m" 500 -
Traceback (most recent call last):
  File "/usr/local/lib/python3.10/dist-packages/flask/app.py", line 1498, in __call__
    return self.wsgi_app(environ, start_response)
  File "/usr/local/lib/python3.10/dist-packages/flask/app.py", line 1476, in wsgi_app
    response = self.handle_exception(e)
  File "/usr/local/lib/python3.10/dist-packages/flask/app.py", line 1473, in wsgi_app
    response = self.full_dispatch_request()
  File "/usr/local/lib/python3.10/dist-packages/flask/app.py", line 882, in full_dispatch_request
    rv = self.handle_user_exception(e)
  File "/usr/local/lib/python3.10/dist-packages/flask/app.py", line 880, in full_dispatch_request
    rv = self.dispatch_request()
  File "/usr/local/lib/python3.10/dist-packages/flask/app.py", line 865, in dispatch_request
    return self.ensure_sync(self.view_functions[rule.endpoint])(**view_args)  # type: ignore[no-any-return]
  File "/mnt/c/Users/Aryan/Desktop/m122_live_currency/Code/app.py", line 79, in home
    btc_price = cmc.getPrice('BTC')['data']['BTC']['quote']['USD']['price']
KeyError: 'data'
127.0.0.1 - - [05/May/2024 16:08:08] "[36mGET /?__debugger__=yes&cmd=resource&f=style.css HTTP/1.1[0m" 304 -
127.0.0.1 - - [05/May/2024 16:08:08] "[36mGET /?__debugger__=yes&cmd=resource&f=debugger.js HTTP/1.1[0m" 304 -
127.0.0.1 - - [05/May/2024 16:08:08] "[36mGET /?__debugger__=yes&cmd=resource&f=console.png HTTP/1.1[0m" 304 -
127.0.0.1 - - [05/May/2024 16:08:08] "[36mGET /?__debugger__=yes&cmd=resource&f=console.png HTTP/1.1[0m" 304 -
127.0.0.1 - - [05/May/2024 16:10:41] "[35m[1mGET / HTTP/1.1[0m" 500 -
Traceback (most recent call last):
  File "/usr/local/lib/python3.10/dist-packages/flask/app.py", line 1498, in __call__
    return self.wsgi_app(environ, start_response)
  File "/usr/local/lib/python3.10/dist-packages/flask/app.py", line 1476, in wsgi_app
    response = self.handle_exception(e)
  File "/usr/local/lib/python3.10/dist-packages/flask/app.py", line 1473, in wsgi_app
    response = self.full_dispatch_request()
  File "/usr/local/lib/python3.10/dist-packages/flask/app.py", line 882, in full_dispatch_request
    rv = self.handle_user_exception(e)
  File "/usr/local/lib/python3.10/dist-packages/flask/app.py", line 880, in full_dispatch_request
    rv = self.dispatch_request()
  File "/usr/local/lib/python3.10/dist-packages/flask/app.py", line 865, in dispatch_request
    return self.ensure_sync(self.view_functions[rule.endpoint])(**view_args)  # type: ignore[no-any-return]
  File "/mnt/c/Users/Aryan/Desktop/m122_live_currency/Code/app.py", line 79, in home
    btc_price = cmc.getPrice('BTC')['data']['BTC']['quote']['USD']['price']
KeyError: 'data'
127.0.0.1 - - [05/May/2024 16:10:41] "[36mGET /?__debugger__=yes&cmd=resource&f=style.css HTTP/1.1[0m" 304 -
127.0.0.1 - - [05/May/2024 16:10:41] "[36mGET /?__debugger__=yes&cmd=resource&f=debugger.js HTTP/1.1[0m" 304 -
127.0.0.1 - - [05/May/2024 16:10:41] "[36mGET /?__debugger__=yes&cmd=resource&f=console.png HTTP/1.1[0m" 304 -
127.0.0.1 - - [05/May/2024 16:10:42] "[36mGET /?__debugger__=yes&cmd=resource&f=console.png HTTP/1.1[0m" 304 -
127.0.0.1 - - [05/May/2024 16:11:32] "[35m[1mGET / HTTP/1.1[0m" 500 -
Traceback (most recent call last):
  File "/usr/local/lib/python3.10/dist-packages/flask/app.py", line 1498, in __call__
    return self.wsgi_app(environ, start_response)
  File "/usr/local/lib/python3.10/dist-packages/flask/app.py", line 1476, in wsgi_app
    response = self.handle_exception(e)
  File "/usr/local/lib/python3.10/dist-packages/flask/app.py", line 1473, in wsgi_app
    response = self.full_dispatch_request()
  File "/usr/local/lib/python3.10/dist-packages/flask/app.py", line 882, in full_dispatch_request
    rv = self.handle_user_exception(e)
  File "/usr/local/lib/python3.10/dist-packages/flask/app.py", line 880, in full_dispatch_request
    rv = self.dispatch_request()
  File "/usr/local/lib/python3.10/dist-packages/flask/app.py", line 865, in dispatch_request
    return self.ensure_sync(self.view_functions[rule.endpoint])(**view_args)  # type: ignore[no-any-return]
  File "/mnt/c/Users/Aryan/Desktop/m122_live_currency/Code/app.py", line 79, in home
    btc_price = cmc.getPrice('BTC')['data']['BTC']['quote']['USD']['price']
KeyError: 'data'
127.0.0.1 - - [05/May/2024 16:11:32] "[36mGET /?__debugger__=yes&cmd=resource&f=style.css HTTP/1.1[0m" 304 -
127.0.0.1 - - [05/May/2024 16:11:32] "[36mGET /?__debugger__=yes&cmd=resource&f=debugger.js HTTP/1.1[0m" 304 -
127.0.0.1 - - [05/May/2024 16:11:32] "[36mGET /?__debugger__=yes&cmd=resource&f=console.png HTTP/1.1[0m" 304 -
127.0.0.1 - - [05/May/2024 16:12:19] "[35m[1mGET / HTTP/1.1[0m" 500 -
Traceback (most recent call last):
  File "/usr/local/lib/python3.10/dist-packages/flask/app.py", line 1498, in __call__
    return self.wsgi_app(environ, start_response)
  File "/usr/local/lib/python3.10/dist-packages/flask/app.py", line 1476, in wsgi_app
    response = self.handle_exception(e)
  File "/usr/local/lib/python3.10/dist-packages/flask/app.py", line 1473, in wsgi_app
    response = self.full_dispatch_request()
  File "/usr/local/lib/python3.10/dist-packages/flask/app.py", line 882, in full_dispatch_request
    rv = self.handle_user_exception(e)
  File "/usr/local/lib/python3.10/dist-packages/flask/app.py", line 880, in full_dispatch_request
    rv = self.dispatch_request()
  File "/usr/local/lib/python3.10/dist-packages/flask/app.py", line 865, in dispatch_request
    return self.ensure_sync(self.view_functions[rule.endpoint])(**view_args)  # type: ignore[no-any-return]
  File "/mnt/c/Users/Aryan/Desktop/m122_live_currency/Code/app.py", line 79, in home
    btc_price = cmc.getPrice('BTC')['data']['BTC']['quote']['USD']['price']
KeyError: 'data'
127.0.0.1 - - [05/May/2024 16:12:19] "[36mGET /?__debugger__=yes&cmd=resource&f=style.css HTTP/1.1[0m" 304 -
127.0.0.1 - - [05/May/2024 16:12:19] "[36mGET /?__debugger__=yes&cmd=resource&f=debugger.js HTTP/1.1[0m" 304 -
127.0.0.1 - - [05/May/2024 16:12:19] "[36mGET /?__debugger__=yes&cmd=resource&f=console.png HTTP/1.1[0m" 304 -
127.0.0.1 - - [05/May/2024 16:12:19] "[36mGET /?__debugger__=yes&cmd=resource&f=console.png HTTP/1.1[0m" 304 -
127.0.0.1 - - [05/May/2024 16:12:21] "[35m[1mGET / HTTP/1.1[0m" 500 -
Traceback (most recent call last):
  File "/usr/local/lib/python3.10/dist-packages/flask/app.py", line 1498, in __call__
    return self.wsgi_app(environ, start_response)
  File "/usr/local/lib/python3.10/dist-packages/flask/app.py", line 1476, in wsgi_app
    response = self.handle_exception(e)
  File "/usr/local/lib/python3.10/dist-packages/flask/app.py", line 1473, in wsgi_app
    response = self.full_dispatch_request()
  File "/usr/local/lib/python3.10/dist-packages/flask/app.py", line 882, in full_dispatch_request
    rv = self.handle_user_exception(e)
  File "/usr/local/lib/python3.10/dist-packages/flask/app.py", line 880, in full_dispatch_request
    rv = self.dispatch_request()
  File "/usr/local/lib/python3.10/dist-packages/flask/app.py", line 865, in dispatch_request
    return self.ensure_sync(self.view_functions[rule.endpoint])(**view_args)  # type: ignore[no-any-return]
  File "/mnt/c/Users/Aryan/Desktop/m122_live_currency/Code/app.py", line 79, in home
    btc_price = cmc.getPrice('BTC')['data']['BTC']['quote']['USD']['price']
KeyError: 'data'
127.0.0.1 - - [05/May/2024 16:12:21] "[36mGET /?__debugger__=yes&cmd=resource&f=style.css HTTP/1.1[0m" 304 -
127.0.0.1 - - [05/May/2024 16:12:21] "[36mGET /?__debugger__=yes&cmd=resource&f=debugger.js HTTP/1.1[0m" 304 -
127.0.0.1 - - [05/May/2024 16:12:21] "[36mGET /?__debugger__=yes&cmd=resource&f=console.png HTTP/1.1[0m" 304 -
127.0.0.1 - - [05/May/2024 16:12:21] "[36mGET /?__debugger__=yes&cmd=resource&f=console.png HTTP/1.1[0m" 304 -
127.0.0.1 - - [05/May/2024 16:12:21] "[35m[1mGET / HTTP/1.1[0m" 500 -
Traceback (most recent call last):
  File "/usr/local/lib/python3.10/dist-packages/flask/app.py", line 1498, in __call__
    return self.wsgi_app(environ, start_response)
  File "/usr/local/lib/python3.10/dist-packages/flask/app.py", line 1476, in wsgi_app
    response = self.handle_exception(e)
  File "/usr/local/lib/python3.10/dist-packages/flask/app.py", line 1473, in wsgi_app
    response = self.full_dispatch_request()
  File "/usr/local/lib/python3.10/dist-packages/flask/app.py", line 882, in full_dispatch_request
    rv = self.handle_user_exception(e)
  File "/usr/local/lib/python3.10/dist-packages/flask/app.py", line 880, in full_dispatch_request
    rv = self.dispatch_request()
  File "/usr/local/lib/python3.10/dist-packages/flask/app.py", line 865, in dispatch_request
    return self.ensure_sync(self.view_functions[rule.endpoint])(**view_args)  # type: ignore[no-any-return]
  File "/mnt/c/Users/Aryan/Desktop/m122_live_currency/Code/app.py", line 79, in home
    btc_price = cmc.getPrice('BTC')['data']['BTC']['quote']['USD']['price']
KeyError: 'data'
127.0.0.1 - - [05/May/2024 16:12:21] "[36mGET /?__debugger__=yes&cmd=resource&f=style.css HTTP/1.1[0m" 304 -
127.0.0.1 - - [05/May/2024 16:12:21] "[36mGET /?__debugger__=yes&cmd=resource&f=debugger.js HTTP/1.1[0m" 304 -
127.0.0.1 - - [05/May/2024 16:12:21] "[36mGET /?__debugger__=yes&cmd=resource&f=console.png HTTP/1.1[0m" 304 -
127.0.0.1 - - [05/May/2024 16:12:22] "[36mGET /?__debugger__=yes&cmd=resource&f=console.png HTTP/1.1[0m" 304 -
127.0.0.1 - - [05/May/2024 16:12:22] "[35m[1mGET / HTTP/1.1[0m" 500 -
127.0.0.1 - - [05/May/2024 16:12:22] "[35m[1mGET / HTTP/1.1[0m" 500 -
127.0.0.1 - - [05/May/2024 16:12:22] "[35m[1mGET / HTTP/1.1[0m" 500 -
127.0.0.1 - - [05/May/2024 16:12:22] "[35m[1mGET / HTTP/1.1[0m" 500 -
127.0.0.1 - - [05/May/2024 16:12:23] "[35m[1mGET / HTTP/1.1[0m" 500 -
Traceback (most recent call last):
  File "/usr/local/lib/python3.10/dist-packages/flask/app.py", line 1498, in __call__
    return self.wsgi_app(environ, start_response)
  File "/usr/local/lib/python3.10/dist-packages/flask/app.py", line 1476, in wsgi_app
    response = self.handle_exception(e)
  File "/usr/local/lib/python3.10/dist-packages/flask/app.py", line 1473, in wsgi_app
    response = self.full_dispatch_request()
  File "/usr/local/lib/python3.10/dist-packages/flask/app.py", line 882, in full_dispatch_request
    rv = self.handle_user_exception(e)
  File "/usr/local/lib/python3.10/dist-packages/flask/app.py", line 880, in full_dispatch_request
    rv = self.dispatch_request()
  File "/usr/local/lib/python3.10/dist-packages/flask/app.py", line 865, in dispatch_request
    return self.ensure_sync(self.view_functions[rule.endpoint])(**view_args)  # type: ignore[no-any-return]
  File "/mnt/c/Users/Aryan/Desktop/m122_live_currency/Code/app.py", line 79, in home
    btc_price = cmc.getPrice('BTC')['data']['BTC']['quote']['USD']['price']
KeyError: 'data'
127.0.0.1 - - [05/May/2024 16:12:23] "[36mGET /?__debugger__=yes&cmd=resource&f=style.css HTTP/1.1[0m" 304 -
127.0.0.1 - - [05/May/2024 16:12:23] "[36mGET /?__debugger__=yes&cmd=resource&f=debugger.js HTTP/1.1[0m" 304 -
127.0.0.1 - - [05/May/2024 16:12:23] "[36mGET /?__debugger__=yes&cmd=resource&f=console.png HTTP/1.1[0m" 304 -
127.0.0.1 - - [05/May/2024 16:12:23] "[36mGET /?__debugger__=yes&cmd=resource&f=console.png HTTP/1.1[0m" 304 -
127.0.0.1 - - [05/May/2024 16:12:34] "[35m[1mGET / HTTP/1.1[0m" 500 -
Traceback (most recent call last):
  File "/usr/local/lib/python3.10/dist-packages/flask/app.py", line 1498, in __call__
    return self.wsgi_app(environ, start_response)
  File "/usr/local/lib/python3.10/dist-packages/flask/app.py", line 1476, in wsgi_app
    response = self.handle_exception(e)
  File "/usr/local/lib/python3.10/dist-packages/flask/app.py", line 1473, in wsgi_app
    response = self.full_dispatch_request()
  File "/usr/local/lib/python3.10/dist-packages/flask/app.py", line 882, in full_dispatch_request
    rv = self.handle_user_exception(e)
  File "/usr/local/lib/python3.10/dist-packages/flask/app.py", line 880, in full_dispatch_request
    rv = self.dispatch_request()
  File "/usr/local/lib/python3.10/dist-packages/flask/app.py", line 865, in dispatch_request
    return self.ensure_sync(self.view_functions[rule.endpoint])(**view_args)  # type: ignore[no-any-return]
  File "/mnt/c/Users/Aryan/Desktop/m122_live_currency/Code/app.py", line 79, in home
    btc_price = cmc.getPrice('BTC')['data']['BTC']['quote']['USD']['price']
KeyError: 'data'
127.0.0.1 - - [05/May/2024 16:12:34] "[36mGET /?__debugger__=yes&cmd=resource&f=debugger.js HTTP/1.1[0m" 304 -
127.0.0.1 - - [05/May/2024 16:12:34] "[36mGET /?__debugger__=yes&cmd=resource&f=style.css HTTP/1.1[0m" 304 -
127.0.0.1 - - [05/May/2024 16:12:34] "[36mGET /?__debugger__=yes&cmd=resource&f=console.png HTTP/1.1[0m" 304 -
127.0.0.1 - - [05/May/2024 16:12:34] "[36mGET /?__debugger__=yes&cmd=resource&f=console.png HTTP/1.1[0m" 304 -
127.0.0.1 - - [05/May/2024 16:12:35] "[35m[1mGET / HTTP/1.1[0m" 500 -
Traceback (most recent call last):
  File "/usr/local/lib/python3.10/dist-packages/flask/app.py", line 1498, in __call__
    return self.wsgi_app(environ, start_response)
  File "/usr/local/lib/python3.10/dist-packages/flask/app.py", line 1476, in wsgi_app
    response = self.handle_exception(e)
  File "/usr/local/lib/python3.10/dist-packages/flask/app.py", line 1473, in wsgi_app
    response = self.full_dispatch_request()
  File "/usr/local/lib/python3.10/dist-packages/flask/app.py", line 882, in full_dispatch_request
    rv = self.handle_user_exception(e)
  File "/usr/local/lib/python3.10/dist-packages/flask/app.py", line 880, in full_dispatch_request
    rv = self.dispatch_request()
  File "/usr/local/lib/python3.10/dist-packages/flask/app.py", line 865, in dispatch_request
    return self.ensure_sync(self.view_functions[rule.endpoint])(**view_args)  # type: ignore[no-any-return]
  File "/mnt/c/Users/Aryan/Desktop/m122_live_currency/Code/app.py", line 79, in home
    btc_price = cmc.getPrice('BTC')['data']['BTC']['quote']['USD']['price']
KeyError: 'data'
127.0.0.1 - - [05/May/2024 16:12:35] "[36mGET /?__debugger__=yes&cmd=resource&f=debugger.js HTTP/1.1[0m" 304 -
127.0.0.1 - - [05/May/2024 16:12:35] "[36mGET /?__debugger__=yes&cmd=resource&f=style.css HTTP/1.1[0m" 304 -
127.0.0.1 - - [05/May/2024 16:12:35] "[36mGET /?__debugger__=yes&cmd=resource&f=console.png HTTP/1.1[0m" 304 -
127.0.0.1 - - [05/May/2024 16:12:35] "[36mGET /?__debugger__=yes&cmd=resource&f=console.png HTTP/1.1[0m" 304 -
127.0.0.1 - - [05/May/2024 16:12:37] "[35m[1mGET / HTTP/1.1[0m" 500 -
Traceback (most recent call last):
  File "/usr/local/lib/python3.10/dist-packages/flask/app.py", line 1498, in __call__
    return self.wsgi_app(environ, start_response)
  File "/usr/local/lib/python3.10/dist-packages/flask/app.py", line 1476, in wsgi_app
    response = self.handle_exception(e)
  File "/usr/local/lib/python3.10/dist-packages/flask/app.py", line 1473, in wsgi_app
    response = self.full_dispatch_request()
  File "/usr/local/lib/python3.10/dist-packages/flask/app.py", line 882, in full_dispatch_request
    rv = self.handle_user_exception(e)
  File "/usr/local/lib/python3.10/dist-packages/flask/app.py", line 880, in full_dispatch_request
    rv = self.dispatch_request()
  File "/usr/local/lib/python3.10/dist-packages/flask/app.py", line 865, in dispatch_request
    return self.ensure_sync(self.view_functions[rule.endpoint])(**view_args)  # type: ignore[no-any-return]
  File "/mnt/c/Users/Aryan/Desktop/m122_live_currency/Code/app.py", line 79, in home
    btc_price = cmc.getPrice('BTC')['data']['BTC']['quote']['USD']['price']
KeyError: 'data'
127.0.0.1 - - [05/May/2024 16:12:37] "[36mGET /?__debugger__=yes&cmd=resource&f=debugger.js HTTP/1.1[0m" 304 -
127.0.0.1 - - [05/May/2024 16:12:37] "[36mGET /?__debugger__=yes&cmd=resource&f=style.css HTTP/1.1[0m" 304 -
127.0.0.1 - - [05/May/2024 16:12:37] "[36mGET /?__debugger__=yes&cmd=resource&f=console.png HTTP/1.1[0m" 304 -
127.0.0.1 - - [05/May/2024 16:12:37] "[36mGET /?__debugger__=yes&cmd=resource&f=console.png HTTP/1.1[0m" 304 -
127.0.0.1 - - [05/May/2024 16:18:07] "[35m[1mGET / HTTP/1.1[0m" 500 -
Traceback (most recent call last):
  File "/usr/local/lib/python3.10/dist-packages/flask/app.py", line 1498, in __call__
    return self.wsgi_app(environ, start_response)
  File "/usr/local/lib/python3.10/dist-packages/flask/app.py", line 1476, in wsgi_app
    response = self.handle_exception(e)
  File "/usr/local/lib/python3.10/dist-packages/flask/app.py", line 1473, in wsgi_app
    response = self.full_dispatch_request()
  File "/usr/local/lib/python3.10/dist-packages/flask/app.py", line 882, in full_dispatch_request
    rv = self.handle_user_exception(e)
  File "/usr/local/lib/python3.10/dist-packages/flask/app.py", line 880, in full_dispatch_request
    rv = self.dispatch_request()
  File "/usr/local/lib/python3.10/dist-packages/flask/app.py", line 865, in dispatch_request
    return self.ensure_sync(self.view_functions[rule.endpoint])(**view_args)  # type: ignore[no-any-return]
  File "/mnt/c/Users/Aryan/Desktop/m122_live_currency/Code/app.py", line 79, in home
    btc_price = cmc.getPrice('BTC')['data']['BTC']['quote']['USD']['price']
KeyError: 'data'
127.0.0.1 - - [05/May/2024 16:18:07] "[36mGET /?__debugger__=yes&cmd=resource&f=style.css HTTP/1.1[0m" 304 -
127.0.0.1 - - [05/May/2024 16:18:07] "[36mGET /?__debugger__=yes&cmd=resource&f=debugger.js HTTP/1.1[0m" 304 -
127.0.0.1 - - [05/May/2024 16:18:07] "[36mGET /?__debugger__=yes&cmd=resource&f=console.png HTTP/1.1[0m" 304 -
127.0.0.1 - - [05/May/2024 16:18:07] "[36mGET /?__debugger__=yes&cmd=resource&f=console.png HTTP/1.1[0m" 304 -
127.0.0.1 - - [05/May/2024 16:23:11] "[35m[1mGET / HTTP/1.1[0m" 500 -
Traceback (most recent call last):
  File "/usr/local/lib/python3.10/dist-packages/flask/app.py", line 1498, in __call__
    return self.wsgi_app(environ, start_response)
  File "/usr/local/lib/python3.10/dist-packages/flask/app.py", line 1476, in wsgi_app
    response = self.handle_exception(e)
  File "/usr/local/lib/python3.10/dist-packages/flask/app.py", line 1473, in wsgi_app
    response = self.full_dispatch_request()
  File "/usr/local/lib/python3.10/dist-packages/flask/app.py", line 882, in full_dispatch_request
    rv = self.handle_user_exception(e)
  File "/usr/local/lib/python3.10/dist-packages/flask/app.py", line 880, in full_dispatch_request
    rv = self.dispatch_request()
  File "/usr/local/lib/python3.10/dist-packages/flask/app.py", line 865, in dispatch_request
    return self.ensure_sync(self.view_functions[rule.endpoint])(**view_args)  # type: ignore[no-any-return]
  File "/mnt/c/Users/Aryan/Desktop/m122_live_currency/Code/app.py", line 79, in home
    btc_price = cmc.getPrice('BTC')['data']['BTC']['quote']['USD']['price']
KeyError: 'data'
127.0.0.1 - - [05/May/2024 16:23:11] "[36mGET /?__debugger__=yes&cmd=resource&f=style.css HTTP/1.1[0m" 304 -
127.0.0.1 - - [05/May/2024 16:23:11] "[36mGET /?__debugger__=yes&cmd=resource&f=debugger.js HTTP/1.1[0m" 304 -
127.0.0.1 - - [05/May/2024 16:23:11] "[36mGET /?__debugger__=yes&cmd=resource&f=console.png HTTP/1.1[0m" 304 -
127.0.0.1 - - [05/May/2024 16:23:11] "[36mGET /?__debugger__=yes&cmd=resource&f=console.png HTTP/1.1[0m" 304 -
127.0.0.1 - - [05/May/2024 16:23:13] "[35m[1mGET / HTTP/1.1[0m" 500 -
Traceback (most recent call last):
  File "/usr/local/lib/python3.10/dist-packages/flask/app.py", line 1498, in __call__
    return self.wsgi_app(environ, start_response)
  File "/usr/local/lib/python3.10/dist-packages/flask/app.py", line 1476, in wsgi_app
    response = self.handle_exception(e)
  File "/usr/local/lib/python3.10/dist-packages/flask/app.py", line 1473, in wsgi_app
    response = self.full_dispatch_request()
  File "/usr/local/lib/python3.10/dist-packages/flask/app.py", line 882, in full_dispatch_request
    rv = self.handle_user_exception(e)
  File "/usr/local/lib/python3.10/dist-packages/flask/app.py", line 880, in full_dispatch_request
    rv = self.dispatch_request()
  File "/usr/local/lib/python3.10/dist-packages/flask/app.py", line 865, in dispatch_request
    return self.ensure_sync(self.view_functions[rule.endpoint])(**view_args)  # type: ignore[no-any-return]
  File "/mnt/c/Users/Aryan/Desktop/m122_live_currency/Code/app.py", line 79, in home
    btc_price = cmc.getPrice('BTC')['data']['BTC']['quote']['USD']['price']
KeyError: 'data'
127.0.0.1 - - [05/May/2024 16:23:13] "[36mGET /?__debugger__=yes&cmd=resource&f=style.css HTTP/1.1[0m" 304 -
127.0.0.1 - - [05/May/2024 16:23:13] "[36mGET /?__debugger__=yes&cmd=resource&f=debugger.js HTTP/1.1[0m" 304 -
127.0.0.1 - - [05/May/2024 16:23:13] "[36mGET /?__debugger__=yes&cmd=resource&f=console.png HTTP/1.1[0m" 304 -
127.0.0.1 - - [05/May/2024 16:23:13] "[36mGET /?__debugger__=yes&cmd=resource&f=console.png HTTP/1.1[0m" 304 -
127.0.0.1 - - [05/May/2024 16:23:14] "[35m[1mGET / HTTP/1.1[0m" 500 -
Traceback (most recent call last):
  File "/usr/local/lib/python3.10/dist-packages/flask/app.py", line 1498, in __call__
    return self.wsgi_app(environ, start_response)
  File "/usr/local/lib/python3.10/dist-packages/flask/app.py", line 1476, in wsgi_app
    response = self.handle_exception(e)
  File "/usr/local/lib/python3.10/dist-packages/flask/app.py", line 1473, in wsgi_app
    response = self.full_dispatch_request()
  File "/usr/local/lib/python3.10/dist-packages/flask/app.py", line 882, in full_dispatch_request
    rv = self.handle_user_exception(e)
  File "/usr/local/lib/python3.10/dist-packages/flask/app.py", line 880, in full_dispatch_request
    rv = self.dispatch_request()
  File "/usr/local/lib/python3.10/dist-packages/flask/app.py", line 865, in dispatch_request
    return self.ensure_sync(self.view_functions[rule.endpoint])(**view_args)  # type: ignore[no-any-return]
  File "/mnt/c/Users/Aryan/Desktop/m122_live_currency/Code/app.py", line 79, in home
    btc_price = cmc.getPrice('BTC')['data']['BTC']['quote']['USD']['price']
KeyError: 'data'
127.0.0.1 - - [05/May/2024 16:23:14] "[36mGET /?__debugger__=yes&cmd=resource&f=style.css HTTP/1.1[0m" 304 -
127.0.0.1 - - [05/May/2024 16:23:14] "[36mGET /?__debugger__=yes&cmd=resource&f=debugger.js HTTP/1.1[0m" 304 -
127.0.0.1 - - [05/May/2024 16:23:14] "[36mGET /?__debugger__=yes&cmd=resource&f=console.png HTTP/1.1[0m" 304 -
127.0.0.1 - - [05/May/2024 16:23:14] "[36mGET /?__debugger__=yes&cmd=resource&f=console.png HTTP/1.1[0m" 304 -
127.0.0.1 - - [05/May/2024 16:25:59] "[35m[1mGET / HTTP/1.1[0m" 500 -
Traceback (most recent call last):
  File "/usr/local/lib/python3.10/dist-packages/flask/app.py", line 1498, in __call__
    return self.wsgi_app(environ, start_response)
  File "/usr/local/lib/python3.10/dist-packages/flask/app.py", line 1476, in wsgi_app
    response = self.handle_exception(e)
  File "/usr/local/lib/python3.10/dist-packages/flask/app.py", line 1473, in wsgi_app
    response = self.full_dispatch_request()
  File "/usr/local/lib/python3.10/dist-packages/flask/app.py", line 882, in full_dispatch_request
    rv = self.handle_user_exception(e)
  File "/usr/local/lib/python3.10/dist-packages/flask/app.py", line 880, in full_dispatch_request
    rv = self.dispatch_request()
  File "/usr/local/lib/python3.10/dist-packages/flask/app.py", line 865, in dispatch_request
    return self.ensure_sync(self.view_functions[rule.endpoint])(**view_args)  # type: ignore[no-any-return]
  File "/mnt/c/Users/Aryan/Desktop/m122_live_currency/Code/app.py", line 79, in home
    btc_price = cmc.getPrice('BTC')['data']['BTC']['quote']['USD']['price']
KeyError: 'data'
127.0.0.1 - - [05/May/2024 16:25:59] "[36mGET /?__debugger__=yes&cmd=resource&f=style.css HTTP/1.1[0m" 304 -
127.0.0.1 - - [05/May/2024 16:25:59] "[36mGET /?__debugger__=yes&cmd=resource&f=debugger.js HTTP/1.1[0m" 304 -
127.0.0.1 - - [05/May/2024 16:25:59] "[36mGET /?__debugger__=yes&cmd=resource&f=console.png HTTP/1.1[0m" 304 -
127.0.0.1 - - [05/May/2024 16:25:59] "[36mGET /?__debugger__=yes&cmd=resource&f=console.png HTTP/1.1[0m" 304 -
 * Detected change in '/mnt/c/Users/Aryan/Desktop/m122_live_currency/Code/app.py', reloading
 * Restarting with stat
 * Debugger is active!
 * Debugger PIN: 100-709-659
127.0.0.1 - - [05/May/2024 16:27:53] "[35m[1mGET / HTTP/1.1[0m" 500 -
Traceback (most recent call last):
  File "/usr/local/lib/python3.10/dist-packages/flask/app.py", line 1498, in __call__
    return self.wsgi_app(environ, start_response)
  File "/usr/local/lib/python3.10/dist-packages/flask/app.py", line 1476, in wsgi_app
    response = self.handle_exception(e)
  File "/usr/local/lib/python3.10/dist-packages/flask/app.py", line 1473, in wsgi_app
    response = self.full_dispatch_request()
  File "/usr/local/lib/python3.10/dist-packages/flask/app.py", line 882, in full_dispatch_request
    rv = self.handle_user_exception(e)
  File "/usr/local/lib/python3.10/dist-packages/flask/app.py", line 880, in full_dispatch_request
    rv = self.dispatch_request()
  File "/usr/local/lib/python3.10/dist-packages/flask/app.py", line 865, in dispatch_request
    return self.ensure_sync(self.view_functions[rule.endpoint])(**view_args)  # type: ignore[no-any-return]
  File "/mnt/c/Users/Aryan/Desktop/m122_live_currency/Code/app.py", line 79, in home
    btc_price = cmc.getPrice('BTC')['data']['BTC']['quote']['USD']['price']
KeyError: 'data'
127.0.0.1 - - [05/May/2024 16:27:53] "[36mGET /?__debugger__=yes&cmd=resource&f=debugger.js HTTP/1.1[0m" 304 -
127.0.0.1 - - [05/May/2024 16:27:53] "[36mGET /?__debugger__=yes&cmd=resource&f=style.css HTTP/1.1[0m" 304 -
127.0.0.1 - - [05/May/2024 16:27:53] "[36mGET /?__debugger__=yes&cmd=resource&f=console.png HTTP/1.1[0m" 304 -
 * Detected change in '/mnt/c/Users/Aryan/Desktop/m122_live_currency/Code/email.py', reloading
 * Restarting with stat
Traceback (most recent call last):
  File "/mnt/c/Users/Aryan/Desktop/m122_live_currency/Code/app.py", line 1, in <module>
    from flask import Flask, render_template
  File "/usr/local/lib/python3.10/dist-packages/flask/__init__.py", line 5, in <module>
    from . import json as json
  File "/usr/local/lib/python3.10/dist-packages/flask/json/__init__.py", line 6, in <module>
    from ..globals import current_app
  File "/usr/local/lib/python3.10/dist-packages/flask/globals.py", line 6, in <module>
    from werkzeug.local import LocalProxy
  File "/usr/local/lib/python3.10/dist-packages/werkzeug/__init__.py", line 5, in <module>
    from .serving import run_simple as run_simple
  File "/usr/local/lib/python3.10/dist-packages/werkzeug/serving.py", line 27, in <module>
    from http.server import BaseHTTPRequestHandler
  File "/usr/lib/python3.10/http/server.py", line 92, in <module>
    import email.utils
  File "/mnt/c/Users/Aryan/Desktop/m122_live_currency/Code/email.py", line 2, in <module>
    import smtplib
  File "/usr/lib/python3.10/smtplib.py", line 47, in <module>
    import email.utils
ModuleNotFoundError: No module named 'email.utils'; 'email' is not a package
Error in sys.excepthook:
Traceback (most recent call last):
  File "/usr/lib/python3/dist-packages/apport_python_hook.py", line 72, in apport_excepthook
    from apport.fileutils import likely_packaged, get_recent_crashes
  File "/usr/lib/python3/dist-packages/apport/__init__.py", line 5, in <module>
    from apport.report import Report
  File "/usr/lib/python3/dist-packages/apport/report.py", line 21, in <module>
    from urllib.request import urlopen
  File "/usr/lib/python3.10/urllib/request.py", line 86, in <module>
    import email
  File "/mnt/c/Users/Aryan/Desktop/m122_live_currency/Code/email.py", line 2, in <module>
    import smtplib
  File "/usr/lib/python3.10/smtplib.py", line 47, in <module>
    import email.utils
ModuleNotFoundError: No module named 'email.utils'; 'email' is not a package

Original exception was:
Traceback (most recent call last):
  File "/mnt/c/Users/Aryan/Desktop/m122_live_currency/Code/app.py", line 1, in <module>
    from flask import Flask, render_template
  File "/usr/local/lib/python3.10/dist-packages/flask/__init__.py", line 5, in <module>
    from . import json as json
  File "/usr/local/lib/python3.10/dist-packages/flask/json/__init__.py", line 6, in <module>
    from ..globals import current_app
  File "/usr/local/lib/python3.10/dist-packages/flask/globals.py", line 6, in <module>
    from werkzeug.local import LocalProxy
  File "/usr/local/lib/python3.10/dist-packages/werkzeug/__init__.py", line 5, in <module>
    from .serving import run_simple as run_simple
  File "/usr/local/lib/python3.10/dist-packages/werkzeug/serving.py", line 27, in <module>
    from http.server import BaseHTTPRequestHandler
  File "/usr/lib/python3.10/http/server.py", line 92, in <module>
    import email.utils
  File "/mnt/c/Users/Aryan/Desktop/m122_live_currency/Code/email.py", line 2, in <module>
    import smtplib
  File "/usr/lib/python3.10/smtplib.py", line 47, in <module>
    import email.utils
ModuleNotFoundError: No module named 'email.utils'; 'email' is not a package
Error sending email: 'NoneType' object has no attribute 'encode'
Error sending email: 'NoneType' object has no attribute 'encode'
Error sending email: 'NoneType' object has no attribute 'encode'
Error sending email: 'NoneType' object has no attribute 'encode'
Error sending email: 'NoneType' object has no attribute 'encode'
Error sending email: 'NoneType' object has no attribute 'encode'
Error sending email: 'NoneType' object has no attribute 'encode'
Error sending email: 'NoneType' object has no attribute 'encode'
Error sending email: 'NoneType' object has no attribute 'encode'
Error sending email: 'NoneType' object has no attribute 'encode'
Error sending email: 'NoneType' object has no attribute 'encode'
/usr/bin/python3: can't open file '/mnt/c/Users/Aryan/Desktop/m122_live_currency/Code/send_email.py': [Errno 2] No such file or directory
